Workbook

Sheet 🏠 Обложка
B2: 🏆 BREAK WAVE RANKING SYSTEM
B3: Рейтинговая система школы брейк-данса Break Wave
B5: 📅 СЕЗОННЫЕ МЕРОПРИЯТИЯ
B6: ❄️ Winter / 🌸 Spring / ☀️ Summer / 🍂 Autumn → x1 балл
B7: 🔥 Break Wave Final → x2 балла
B9: 🎯 СИСТЕМА НАЧИСЛЕНИЯ БАЛЛОВ
B10: 🥇 1 место → 30 баллов | 🥈 2 место → 20 баллов | 🥉 3 место → 10 баллов | 🎫 Участник → 1 балл
B12: 📋 СТРУКТУРА ФАЙЛА
B13: → 👥 Участники | D13: Единый список участников и номинации (заполнить 1 раз)
B14: → ❄️ Winter | D14: Результаты зимнего мероприятия
B15: → 🌸 Spring | D15: Результаты весеннего мероприятия
B16: → ☀️ Summer | D16: Результаты летнего мероприятия
B17: → 🍂 Autumn | D17: Результаты осеннего мероприятия
B18: → 🔥 Final | D18: Финальное мероприятие (баллы x2)
B19: → 📊 Общий рейтинг | D19: Сводная таблица всех баллов за сезон
B20: → 🏆 Дашборд | D20: Топ-3 победителей по каждой номинации

Sheet 👥 Участники
B2: 👥 УЧАСТНИКИ BREAK WAVE
B3: № | C3: Имя участника | D3: Номинация
B4: 1 | C4: Bboy Player | D4: до 6 лет
B5: 2 | C5: Bgirl Puma | D5: Bgirl
B6: 3 | C6: Bboy King | D6: до 6 лет
B7: 4 | C7: Bboy Max-Club | D7: 1 год обучения
B8: 5 | C8: Bboy Nazаr | D8: 1 год обучения
B9: 6 | C9: Bboy Batmort | D9: до 3 лет опыта
B10: 7 | C10: Bboy Лебедь | D10: до 3 лет опыта
B11: 8 | C11: Bboy LaKostya | D11: до 3 лет опыта
B12: 9 | C12: Bboy Svyat | D12: до 3 лет опыта
B13: 10 | C13: Bboy Мастер-ни | D13: до 3 лет опыта
B14: 11 | C14: Bboy Фрол | D14: 1 год обучения
B15: 12 | C15: Bboy Wind | D15: 10-13 лет
... B60: 57 | C60: Bgirl Raura | D60: Bgirl
B61: 58
B62: 59
B63: 60
B64: 61
B65: 62
B66: 63
B67: 64
B68: 65
B69: 66
B70: 67
B71: 68
B72: 69
... B103: 100

Sheet ❄️ Winter
B2: ❄️ Winter — РЕЗУЛЬТАТЫ
B3: № | C3: Имя участника | D3: Номинация | E3: Место (осн.) | F3: Доп. ном.1 | G3: Доп. ном.2 | H3: Доп. ном.3 | I3: Баллы (x1)
B4: ='👥 Участники'!B4 | C4: ='👥 Участники'!C4 | D4: ='👥 Участники'!D4 | E4: 1 | F4: 3 | I4: =IF(AND(C4="",OR(E4="",E4=0)),"",(IF(E4=1,30,IF(E4=2,20,IF(E4=3,10,IF(E4<>"",1,0))))+IF(F4=1,30,IF(F4=2,20,IF(F4=3,10,IF(F4<>"",1,0))))+IF(G4=1,30,IF(G4=2,20,IF(G4=3,10,IF(G4<>"",1,0))))+IF(H4=1,30,IF(H4=2,20,IF(H4=3,10,IF(H4<>"",1,0))))))
B5: ='👥 Участники'!B5 | C5: ='👥 Участники'!C5 | D5: ='👥 Участники'!D5 | E5: 2 | F5: 2 | I5: =IF(AND(C5="",OR(E5="",E5=0)),"",(IF(E5=1,30,IF(E5=2,20,IF(E5=3,10,IF(E5<>"",1,0))))+IF(F5=1,30,IF(F5=2,20,IF(F5=3,10,IF(F5<>"",1,0))))+IF(G5=1,30,IF(G5=2,20,IF(G5=3,10,IF(G5<>"",1,0))))+IF(H5=1,30,IF(H5=2,20,IF(H5=3,10,IF(H5<>"",1,0))))))
B6: ='👥 Участники'!B6 | C6: ='👥 Участники'!C6 | D6: ='👥 Участники'!D6 | E6: 3 | I6: =IF(AND(C6="",OR(E6="",E6=0)),"",(IF(E6=1,30,IF(E6=2,20,IF(E6=3,10,IF(E6<>"",1,0))))+IF(F6=1,30,IF(F6=2,20,IF(F6=3,10,IF(F6<>"",1,0))))+IF(G6=1,30,IF(G6=2,20,IF(G6=3,10,IF(G6<>"",1,0))))+IF(H6=1,30,IF(H6=2,20,IF(H6=3,10,IF(H6<>"",1,0))))))
B7: ='👥 Участники'!B7 | C7: ='👥 Участники'!C7 | D7: ='👥 Участники'!D7 | E7: 1 | I7: =IF(AND(C7="",OR(E7="",E7=0)),"",(IF(E7=1,30,IF(E7=2,20,IF(E7=3,10,IF(E7<>"",1,0))))+IF(F7=1,30,IF(F7=2,20,IF(F7=3,10,IF(F7<>"",1,0))))+IF(G7=1,30,IF(G7=2,20,IF(G7=3,10,IF(G7<>"",1,0))))+IF(H7=1,30,IF(H7=2,20,IF(H7=3,10,IF(H7<>"",1,0))))))
B8: ='👥 Участники'!B8 | C8: ='👥 Участники'!C8 | D8: ='👥 Участники'!D8 | E8: 2 | I8: =IF(AND(C8="",OR(E8="",E8=0)),"",(IF(E8=1,30,IF(E8=2,20,IF(E8=3,10,IF(E8<>"",1,0))))+IF(F8=1,30,IF(F8=2,20,IF(F8=3,10,IF(F8<>"",1,0))))+IF(G8=1,30,IF(G8=2,20,IF(G8=3,10,IF(G8<>"",1,0))))+IF(H8=1,30,IF(H8=2,20,IF(H8=3,10,IF(H8<>"",1,0))))))
B9: ='👥 Участники'!B9 | C9: ='👥 Участники'!C9 | D9: ='👥 Участники'!D9 | E9: 1 | F9: 0 | I9: =IF(AND(C9="",OR(E9="",E9=0)),"",(IF(E9=1,30,IF(E9=2,20,IF(E9=3,10,IF(E9<>"",1,0))))+IF(F9=1,30,IF(F9=2,20,IF(F9=3,10,IF(F9<>"",1,0))))+IF(G9=1,30,IF(G9=2,20,IF(G9=3,10,IF(G9<>"",1,0))))+IF(H9=1,30,IF(H9=2,20,IF(H9=3,10,IF(H9<>"",1,0))))))
B10: ='👥 Участники'!B10 | C10: ='👥 Участники'!C10 | D10: ='👥 Участники'!D10 | E10: 1 | I10: =IF(AND(C10="",OR(E10="",E10=0)),"",(IF(E10=1,30,IF(E10=2,20,IF(E10=3,10,IF(E10<>"",1,0))))+IF(F10=1,30,IF(F10=2,20,IF(F10=3,10,IF(F10<>"",1,0))))+IF(G10=1,30,IF(G10=2,20,IF(G10=3,10,IF(G10<>"",1,0))))+IF(H10=1,30,IF(H10=2,20,IF(H10=3,10,IF(H10<>"",1,0))))))
B11: ='👥 Участники'!B11 | C11: ='👥 Участники'!C11 | D11: ='👥 Участники'!D11 | E11: 1 | I11: =IF(AND(C11="",OR(E11="",E11=0)),"",(IF(E11=1,30,IF(E11=2,20,IF(E11=3,10,IF(E11<>"",1,0))))+IF(F11=1,30,IF(F11=2,20,IF(F11=3,10,IF(F11<>"",1,0))))+IF(G11=1,30,IF(G11=2,20,IF(G11=3,10,IF(G11<>"",1,0))))+IF(H11=1,30,IF(H11=2,20,IF(H11=3,10,IF(H11<>"",1,0))))))
B12: ='👥 Участники'!B12 | C12: ='👥 Участники'!C12 | D12: ='👥 Участники'!D12 | E12: 2 | I12: =IF(AND(C12="",OR(E12="",E12=0)),"",(IF(E12=1,30,IF(E12=2,20,IF(E12=3,10,IF(E12<>"",1,0))))+IF(F12=1,30,IF(F12=2,20,IF(F12=3,10,IF(F12<>"",1,0))))+IF(G12=1,30,IF(G12=2,20,IF(G12=3,10,IF(G12<>"",1,0))))+IF(H12=1,30,IF(H12=2,20,IF(H12=3,10,IF(H12<>"",1,0))))))
B13: ='👥 Участники'!B13 | C13: ='👥 Участники'!C13 | D13: ='👥 Участники'!D13 | E13: 2 | I13: =IF(AND(C13="",OR(E13="",E13=0)),"",(IF(E13=1,30,IF(E13=2,20,IF(E13=3,10,IF(E13<>"",1,0))))+IF(F13=1,30,IF(F13=2,20,IF(F13=3,10,IF(F13<>"",1,0))))+IF(G13=1,30,IF(G13=2,20,IF(G13=3,10,IF(G13<>"",1,0))))+IF(H13=1,30,IF(H13=2,20,IF(H13=3,10,IF(H13<>"",1,0))))))
B14: ='👥 Участники'!B14 | C14: ='👥 Участники'!C14 | D14: ='👥 Участники'!D14 | E14: 0 | F14: 2 | I14: =IF(AND(C14="",OR(E14="",E14=0)),"",(IF(E14=1,30,IF(E14=2,20,IF(E14=3,10,IF(E14<>"",1,0))))+IF(F14=1,30,IF(F14=2,20,IF(F14=3,10,IF(F14<>"",1,0))))+IF(G14=1,30,IF(G14=2,20,IF(G14=3,10,IF(G14<>"",1,0))))+IF(H14=1,30,IF(H14=2,20,IF(H14=3,10,IF(H14<>"",1,0))))))
B15: ='👥 Участники'!B15 | C15: ='👥 Участники'!C15 | D15: ='👥 Участники'!D15 | E15: 1 | I15: =IF(AND(C15="",OR(E15="",E15=0)),"",(IF(E15=1,30,IF(E15=2,20,IF(E15=3,10,IF(E15<>"",1,0))))+IF(F15=1,30,IF(F15=2,20,IF(F15=3,10,IF(F15<>"",1,0))))+IF(G15=1,30,IF(G15=2,20,IF(G15=3,10,IF(G15<>"",1,0))))+IF(H15=1,30,IF(H15=2,20,IF(H15=3,10,IF(H15<>"",1,0))))))
B16: ='👥 Участники'!B16 | C16: ='👥 Участники'!C16 | D16: ='👥 Участники'!D16 | E16: 2 | I16: =IF(AND(C16="",OR(E16="",E16=0)),"",(IF(E16=1,30,IF(E16=2,20,IF(E16=3,10,IF(E16<>"",1,0))))+IF(F16=1,30,IF(F16=2,20,IF(F16=3,10,IF(F16<>"",1,0))))+IF(G16=1,30,IF(G16=2,20,IF(G16=3,10,IF(G16<>"",1,0))))+IF(H16=1,30,IF(H16=2,20,IF(H16=3,10,IF(H16<>"",1,0))))))
B17: ='👥 Участники'!B17 | C17: ='👥 Участники'!C17 | D17: ='👥 Участники'!D17 | E17: 3 | F17: 3 | I17: =IF(AND(C17="",OR(E17="",E17=0)),"",(IF(E17=1,30,IF(E17=2,20,IF(E17=3,10,IF(E17<>"",1,0))))+IF(F17=1,30,IF(F17=2,20,IF(F17=3,10,IF(F17<>"",1,0))))+IF(G17=1,30,IF(G17=2,20,IF(G17=3,10,IF(G17<>"",1,0))))+IF(H17=1,30,IF(H17=2,20,IF(H17=3,10,IF(H17<>"",1,0))))))
B18: ='👥 Участники'!B18 | C18: ='👥 Участники'!C18 | D18: ='👥 Участники'!D18 | E18: 1 | F18: 2 | I18: =IF(AND(C18="",OR(E18="",E18=0)),"",(IF(E18=1,30,IF(E18=2,20,IF(E18=3,10,IF(E18<>"",1,0))))+IF(F18=1,30,IF(F18=2,20,IF(F18=3,10,IF(F18<>"",1,0))))+IF(G18=1,30,IF(G18=2,20,IF(G18=3,10,IF(G18<>"",1,0))))+IF(H18=1,30,IF(H18=2,20,IF(H18=3,10,IF(H18<>"",1,0))))))
B19: ='👥 Участники'!B19 | C19: ='👥 Участники'!C19 | D19: ='👥 Участники'!D19 | E19: 2 | I19: =IF(AND(C19="",OR(E19="",E19=0)),"",(IF(E19=1,30,IF(E19=2,20,IF(E19=3,10,IF(E19<>"",1,0))))+IF(F19=1,30,IF(F19=2,20,IF(F19=3,10,IF(F19<>"",1,0))))+IF(G19=1,30,IF(G19=2,20,IF(G19=3,10,IF(G19<>"",1,0))))+IF(H19=1,30,IF(H19=2,20,IF(H19=3,10,IF(H19<>"",1,0))))))
B20: ='👥 Участники'!B20 | C20: ='👥 Участники'!C20 | D20: ='👥 Участники'!D20 | E20: 1 | I20: =IF(AND(C20="",OR(E20="",E20=0)),"",(IF(E20=1,30,IF(E20=2,20,IF(E20=3,10,IF(E20<>"",1,0))))+IF(F20=1,30,IF(F20=2,20,IF(F20=3,10,IF(F20<>"",1,0))))+IF(G20=1,30,IF(G20=2,20,IF(G20=3,10,IF(G20<>"",1,0))))+IF(H20=1,30,IF(H20=2,20,IF(H20=3,10,IF(H20<>"",1,0))))))
B21: ='👥 Участники'!B21 | C21: ='👥 Участники'!C21 | D21: ='👥 Участники'!D21 | E21: 3 | I21: =IF(AND(C21="",OR(E21="",E21=0)),"",(IF(E21=1,30,IF(E21=2,20,IF(E21=3,10,IF(E21<>"",1,0))))+IF(F21=1,30,IF(F21=2,20,IF(F21=3,10,IF(F21<>"",1,0))))+IF(G21=1,30,IF(G21=2,20,IF(G21=3,10,IF(G21<>"",1,0))))+IF(H21=1,30,IF(H21=2,20,IF(H21=3,10,IF(H21<>"",1,0))))))
B22: ='👥 Участники'!B22 | C22: ='👥 Участники'!C22 | D22: ='👥 Участники'!D22 | F22: 0 | G22: 0 | I22: =IF(AND(C22="",OR(E22="",E22=0)),"",(IF(E22=1,30,IF(E22=2,20,IF(E22=3,10,IF(E22<>"",1,0))))+IF(F22=1,30,IF(F22=2,20,IF(F22=3,10,IF(F22<>"",1,0))))+IF(G22=1,30,IF(G22=2,20,IF(G22=3,10,IF(G22<>"",1,0))))+IF(H22=1,30,IF(H22=2,20,IF(H22=3,10,IF(H22<>"",1,0))))))
B23: ='👥 Участники'!B23 | C23: ='👥 Участники'!C23 | D23: ='👥 Участники'!D23 | F23: 0 | G23: 0 | I23: =IF(AND(C23="",OR(E23="",E23=0)),"",(IF(E23=1,30,IF(E23=2,20,IF(E23=3,10,IF(E23<>"",1,0))))+IF(F23=1,30,IF(F23=2,20,IF(F23=3,10,IF(F23<>"",1,0))))+IF(G23=1,30,IF(G23=2,20,IF(G23=3,10,IF(G23<>"",1,0))))+IF(H23=1,30,IF(H23=2,20,IF(H23=3,10,IF(H23<>"",1,0))))))
B24: ='👥 Участники'!B24 | C24: ='👥 Участники'!C24 | D24: ='👥 Участники'!D24 | E24: 0 | I24: =IF(AND(C24="",OR(E24="",E24=0)),"",(IF(E24=1,30,IF(E24=2,20,IF(E24=3,10,IF(E24<>"",1,0))))+IF(F24=1,30,IF(F24=2,20,IF(F24=3,10,IF(F24<>"",1,0))))+IF(G24=1,30,IF(G24=2,20,IF(G24=3,10,IF(G24<>"",1,0))))+IF(H24=1,30,IF(H24=2,20,IF(H24=3,10,IF(H24<>"",1,0))))))
B25: ='👥 Участники'!B25 | C25: ='👥 Участники'!C25 | D25: ='👥 Участники'!D25 | E25: 0 | I25: =IF(AND(C25="",OR(E25="",E25=0)),"",(IF(E25=1,30,IF(E25=2,20,IF(E25=3,10,IF(E25<>"",1,0))))+IF(F25=1,30,IF(F25=2,20,IF(F25=3,10,IF(F25<>"",1,0))))+IF(G25=1,30,IF(G25=2,20,IF(G25=3,10,IF(G25<>"",1,0))))+IF(H25=1,30,IF(H25=2,20,IF(H25=3,10,IF(H25<>"",1,0))))))
B26: ='👥 Участники'!B26 | C26: ='👥 Участники'!C26 | D26: ='👥 Участники'!D26 | E26: 0 | I26: =IF(AND(C26="",OR(E26="",E26=0)),"",(IF(E26=1,30,IF(E26=2,20,IF(E26=3,10,IF(E26<>"",1,0))))+IF(F26=1,30,IF(F26=2,20,IF(F26=3,10,IF(F26<>"",1,0))))+IF(G26=1,30,IF(G26=2,20,IF(G26=3,10,IF(G26<>"",1,0))))+IF(H26=1,30,IF(H26=2,20,IF(H26=3,10,IF(H26<>"",1,0))))))
B27: ='👥 Участники'!B27 | C27: ='👥 Участники'!C27 | D27: ='👥 Участники'!D27 | E27: 0 | I27: =IF(AND(C27="",OR(E27="",E27=0)),"",(IF(E27=1,30,IF(E27=2,20,IF(E27=3,10,IF(E27<>"",1,0))))+IF(F27=1,30,IF(F27=2,20,IF(F27=3,10,IF(F27<>"",1,0))))+IF(G27=1,30,IF(G27=2,20,IF(G27=3,10,IF(G27<>"",1,0))))+IF(H27=1,30,IF(H27=2,20,IF(H27=3,10,IF(H27<>"",1,0))))))
B28: ='👥 Участники'!B28 | C28: ='👥 Участники'!C28 | D28: ='👥 Участники'!D28 | E28: 0 | I28: =IF(AND(C28="",OR(E28="",E28=0)),"",(IF(E28=1,30,IF(E28=2,20,IF(E28=3,10,IF(E28<>"",1,0))))+IF(F28=1,30,IF(F28=2,20,IF(F28=3,10,IF(F28<>"",1,0))))+IF(G28=1,30,IF(G28=2,20,IF(G28=3,10,IF(G28<>"",1,0))))+IF(H28=1,30,IF(H28=2,20,IF(H28=3,10,IF(H28<>"",1,0))))))
B29: ='👥 Участники'!B29 | C29: ='👥 Участники'!C29 | D29: ='👥 Участники'!D29 | E29: 0 | I29: =IF(AND(C29="",OR(E29="",E29=0)),"",(IF(E29=1,30,IF(E29=2,20,IF(E29=3,10,IF(E29<>"",1,0))))+IF(F29=1,30,IF(F29=2,20,IF(F29=3,10,IF(F29<>"",1,0))))+IF(G29=1,30,IF(G29=2,20,IF(G29=3,10,IF(G29<>"",1,0))))+IF(H29=1,30,IF(H29=2,20,IF(H29=3,10,IF(H29<>"",1,0))))))
B30: ='👥 Участники'!B30 | C30: ='👥 Участники'!C30 | D30: ='👥 Участники'!D30 | E30: 0 | I30: =IF(AND(C30="",OR(E30="",E30=0)),"",(IF(E30=1,30,IF(E30=2,20,IF(E30=3,10,IF(E30<>"",1,0))))+IF(F30=1,30,IF(F30=2,20,IF(F30=3,10,IF(F30<>"",1,0))))+IF(G30=1,30,IF(G30=2,20,IF(G30=3,10,IF(G30<>"",1,0))))+IF(H30=1,30,IF(H30=2,20,IF(H30=3,10,IF(H30<>"",1,0))))))
B31: ='👥 Участники'!B31 | C31: ='👥 Участники'!C31 | D31: ='👥 Участники'!D31 | E31: 0 | I31: =IF(AND(C31="",OR(E31="",E31=0)),"",(IF(E31=1,30,IF(E31=2,20,IF(E31=3,10,IF(E31<>"",1,0))))+IF(F31=1,30,IF(F31=2,20,IF(F31=3,10,IF(F31<>"",1,0))))+IF(G31=1,30,IF(G31=2,20,IF(G31=3,10,IF(G31<>"",1,0))))+IF(H31=1,30,IF(H31=2,20,IF(H31=3,10,IF(H31<>"",1,0))))))
B32: ='👥 Участники'!B32 | C32: ='👥 Участники'!C32 | D32: ='👥 Участники'!D32 | E32: 0 | I32: =IF(AND(C32="",OR(E32="",E32=0)),"",(IF(E32=1,30,IF(E32=2,20,IF(E32=3,10,IF(E32<>"",1,0))))+IF(F32=1,30,IF(F32=2,20,IF(F32=3,10,IF(F32<>"",1,0))))+IF(G32=1,30,IF(G32=2,20,IF(G32=3,10,IF(G32<>"",1,0))))+IF(H32=1,30,IF(H32=2,20,IF(H32=3,10,IF(H32<>"",1,0))))))
B33: ='👥 Участники'!B33 | C33: ='👥 Участники'!C33 | D33: ='👥 Участники'!D33 | E33: 0 | I33: =IF(AND(C33="",OR(E33="",E33=0)),"",(IF(E33=1,30,IF(E33=2,20,IF(E33=3,10,IF(E33<>"",1,0))))+IF(F33=1,30,IF(F33=2,20,IF(F33=3,10,IF(F33<>"",1,0))))+IF(G33=1,30,IF(G33=2,20,IF(G33=3,10,IF(G33<>"",1,0))))+IF(H33=1,30,IF(H33=2,20,IF(H33=3,10,IF(H33<>"",1,0))))))
B34: ='👥 Участники'!B34 | C34: ='👥 Участники'!C34 | D34: ='👥 Участники'!D34 | E34: 3 | I34: =IF(AND(C34="",OR(E34="",E34=0)),"",(IF(E34=1,30,IF(E34=2,20,IF(E34=3,10,IF(E34<>"",1,0))))+IF(F34=1,30,IF(F34=2,20,IF(F34=3,10,IF(F34<>"",1,0))))+IF(G34=1,30,IF(G34=2,20,IF(G34=3,10,IF(G34<>"",1,0))))+IF(H34=1,30,IF(H34=2,20,IF(H34=3,10,IF(H34<>"",1,0))))))
B35: ='👥 Участники'!B35 | C35: ='👥 Участники'!C35 | D35: ='👥 Участники'!D35 | E35: 1 | I35: =IF(AND(C35="",OR(E35="",E35=0)),"",(IF(E35=1,30,IF(E35=2,20,IF(E35=3,10,IF(E35<>"",1,0))))+IF(F35=1,30,IF(F35=2,20,IF(F35=3,10,IF(F35<>"",1,0))))+IF(G35=1,30,IF(G35=2,20,IF(G35=3,10,IF(G35<>"",1,0))))+IF(H35=1,30,IF(H35=2,20,IF(H35=3,10,IF(H35<>"",1,0))))))
B36: ='👥 Участники'!B36 | C36: ='👥 Участники'!C36 | D36: ='👥 Участники'!D36 | I36: =IF(AND(C36="",OR(E36="",E36=0)),"",(IF(E36=1,30,IF(E36=2,20,IF(E36=3,10,IF(E36<>"",1,0))))+IF(F36=1,30,IF(F36=2,20,IF(F36=3,10,IF(F36<>"",1,0))))+IF(G36=1,30,IF(G36=2,20,IF(G36=3,10,IF(G36<>"",1,0))))+IF(H36=1,30,IF(H36=2,20,IF(H36=3,10,IF(H36<>"",1,0))))))
B37: ='👥 Участники'!B37 | C37: ='👥 Участники'!C37 | D37: ='👥 Участники'!D37 | I37: =IF(AND(C37="",OR(E37="",E37=0)),"",(IF(E37=1,30,IF(E37=2,20,IF(E37=3,10,IF(E37<>"",1,0))))+IF(F37=1,30,IF(F37=2,20,IF(F37=3,10,IF(F37<>"",1,0))))+IF(G37=1,30,IF(G37=2,20,IF(G37=3,10,IF(G37<>"",1,0))))+IF(H37=1,30,IF(H37=2,20,IF(H37=3,10,IF(H37<>"",1,0))))))
B38: ='👥 Участники'!B38 | C38: ='👥 Участники'!C38 | D38: ='👥 Участники'!D38 | I38: =IF(AND(C38="",OR(E38="",E38=0)),"",(IF(E38=1,30,IF(E38=2,20,IF(E38=3,10,IF(E38<>"",1,0))))+IF(F38=1,30,IF(F38=2,20,IF(F38=3,10,IF(F38<>"",1,0))))+IF(G38=1,30,IF(G38=2,20,IF(G38=3,10,IF(G38<>"",1,0))))+IF(H38=1,30,IF(H38=2,20,IF(H38=3,10,IF(H38<>"",1,0))))))
B39: ='👥 Участники'!B39 | C39: ='👥 Участники'!C39 | D39: ='👥 Участники'!D39 | I39: =IF(AND(C39="",OR(E39="",E39=0)),"",(IF(E39=1,30,IF(E39=2,20,IF(E39=3,10,IF(E39<>"",1,0))))+IF(F39=1,30,IF(F39=2,20,IF(F39=3,10,IF(F39<>"",1,0))))+IF(G39=1,30,IF(G39=2,20,IF(G39=3,10,IF(G39<>"",1,0))))+IF(H39=1,30,IF(H39=2,20,IF(H39=3,10,IF(H39<>"",1,0))))))
B40: ='👥 Участники'!B40 | C40: ='👥 Участники'!C40 | D40: ='👥 Участники'!D40 | I40: =IF(AND(C40="",OR(E40="",E40=0)),"",(IF(E40=1,30,IF(E40=2,20,IF(E40=3,10,IF(E40<>"",1,0))))+IF(F40=1,30,IF(F40=2,20,IF(F40=3,10,IF(F40<>"",1,0))))+IF(G40=1,30,IF(G40=2,20,IF(G40=3,10,IF(G40<>"",1,0))))+IF(H40=1,30,IF(H40=2,20,IF(H40=3,10,IF(H40<>"",1,0))))))
B41: ='👥 Участники'!B41 | C41: ='👥 Участники'!C41 | D41: ='👥 Участники'!D41 | I41: =IF(AND(C41="",OR(E41="",E41=0)),"",(IF(E41=1,30,IF(E41=2,20,IF(E41=3,10,IF(E41<>"",1,0))))+IF(F41=1,30,IF(F41=2,20,IF(F41=3,10,IF(F41<>"",1,0))))+IF(G41=1,30,IF(G41=2,20,IF(G41=3,10,IF(G41<>"",1,0))))+IF(H41=1,30,IF(H41=2,20,IF(H41=3,10,IF(H41<>"",1,0))))))
...

Sheet 🌸 Spring
B2: 🌸 Spring — РЕЗУЛЬТАТЫ
B3: № | C3: Имя участника | D3: Номинация | E3: Место (осн.) | F3: Доп. ном.1 | G3: Доп. ном.2 | H3: Доп. ном.3 | I3: Баллы (x1)
B4: ='👥 Участники'!B4 | C4: ='👥 Участники'!C4 | D4: ='👥 Участники'!D4 | I4: =IF(AND(C4="",OR(E4="",E4=0)),"",(IF(E4=1,30,IF(E4=2,20,IF(E4=3,10,IF(E4<>"",1,0))))+IF(F4=1,30,IF(F4=2,20,IF(F4=3,10,IF(F4<>"",1,0))))+IF(G4=1,30,IF(G4=2,20,IF(G4=3,10,IF(G4<>"",1,0))))+IF(H4=1,30,IF(H4=2,20,IF(H4=3,10,IF(H4<>"",1,0))))))
B5: ='👥 Участники'!B5 | C5: ='👥 Участники'!C5 | D5: ='👥 Участники'!D5 | I5: =IF(AND(C5="",OR(E5="",E5=0)),"",(IF(E5=1,30,IF(E5=2,20,IF(E5=3,10,IF(E5<>"",1,0))))+IF(F5=1,30,IF(F5=2,20,IF(F5=3,10,IF(F5<>"",1,0))))+IF(G5=1,30,IF(G5=2,20,IF(G5=3,10,IF(G5<>"",1,0))))+IF(H5=1,30,IF(H5=2,20,IF(H5=3,10,IF(H5<>"",1,0))))))
B6: ='👥 Участники'!B6 | C6: ='👥 Участники'!C6 | D6: ='👥 Участники'!D6 | I6: =IF(AND(C6="",OR(E6="",E6=0)),"",(IF(E6=1,30,IF(E6=2,20,IF(E6=3,10,IF(E6<>"",1,0))))+IF(F6=1,30,IF(F6=2,20,IF(F6=3,10,IF(F6<>"",1,0))))+IF(G6=1,30,IF(G6=2,20,IF(G6=3,10,IF(G6<>"",1,0))))+IF(H6=1,30,IF(H6=2,20,IF(H6=3,10,IF(H6<>"",1,0))))))
B7: ='👥 Участники'!B7 | C7: ='👥 Участники'!C7 | D7: ='👥 Участники'!D7 | I7: =IF(AND(C7="",OR(E7="",E7=0)),"",(IF(E7=1,30,IF(E7=2,20,IF(E7=3,10,IF(E7<>"",1,0))))+IF(F7=1,30,IF(F7=2,20,IF(F7=3,10,IF(F7<>"",1,0))))+IF(G7=1,30,IF(G7=2,20,IF(G7=3,10,IF(G7<>"",1,0))))+IF(H7=1,30,IF(H7=2,20,IF(H7=3,10,IF(H7<>"",1,0))))))
B8: ='👥 Участники'!B8 | C8: ='👥 Участники'!C8 | D8: ='👥 Участники'!D8 | I8: =IF(AND(C8="",OR(E8="",E8=0)),"",(IF(E8=1,30,IF(E8=2,20,IF(E8=3,10,IF(E8<>"",1,0))))+IF(F8=1,30,IF(F8=2,20,IF(F8=3,10,IF(F8<>"",1,0))))+IF(G8=1,30,IF(G8=2,20,IF(G8=3,10,IF(G8<>"",1,0))))+IF(H8=1,30,IF(H8=2,20,IF(H8=3,10,IF(H8<>"",1,0))))))
B9: ='👥 Участники'!B9 | C9: ='👥 Участники'!C9 | D9: ='👥 Участники'!D9 | I9: =IF(AND(C9="",OR(E9="",E9=0)),"",(IF(E9=1,30,IF(E9=2,20,IF(E9=3,10,IF(E9<>"",1,0))))+IF(F9=1,30,IF(F9=2,20,IF(F9=3,10,IF(F9<>"",1,0))))+IF(G9=1,30,IF(G9=2,20,IF(G9=3,10,IF(G9<>"",1,0))))+IF(H9=1,30,IF(H9=2,20,IF(H9=3,10,IF(H9<>"",1,0))))))
B10: ='👥 Участники'!B10 | C10: ='👥 Участники'!C10 | D10: ='👥 Участники'!D10 | I10: =IF(AND(C10="",OR(E10="",E10=0)),"",(IF(E10=1,30,IF(E10=2,20,IF(E10=3,10,IF(E10<>"",1,0))))+IF(F10=1,30,IF(F10=2,20,IF(F10=3,10,IF(F10<>"",1,0))))+IF(G10=1,30,IF(G10=2,20,IF(G10=3,10,IF(G10<>"",1,0))))+IF(H10=1,30,IF(H10=2,20,IF(H10=3,10,IF(H10<>"",1,0))))))
B11: ='👥 Участники'!B11 | C11: ='👥 Участники'!C11 | D11: ='👥 Участники'!D11 | I11: =IF(AND(C11="",OR(E11="",E11=0)),"",(IF(E11=1,30,IF(E11=2,20,IF(E11=3,10,IF(E11<>"",1,0))))+IF(F11=1,30,IF(F11=2,20,IF(F11=3,10,IF(F11<>"",1,0))))+IF(G11=1,30,IF(G11=2,20,IF(G11=3,10,IF(G11<>"",1,0))))+IF(H11=1,30,IF(H11=2,20,IF(H11=3,10,IF(H11<>"",1,0))))))
B12: ='👥 Участники'!B12 | C12: ='👥 Участники'!C12 | D12: ='👥 Участники'!D12 | I12: =IF(AND(C12="",OR(E12="",E12=0)),"",(IF(E12=1,30,IF(E12=2,20,IF(E12=3,10,IF(E12<>"",1,0))))+IF(F12=1,30,IF(F12=2,20,IF(F12=3,10,IF(F12<>"",1,0))))+IF(G12=1,30,IF(G12=2,20,IF(G12=3,10,IF(G12<>"",1,0))))+IF(H12=1,30,IF(H12=2,20,IF(H12=3,10,IF(H12<>"",1,0))))))
B13: ='👥 Участники'!B13 | C13: ='👥 Участники'!C13 | D13: ='👥 Участники'!D13 | I13: =IF(AND(C13="",OR(E13="",E13=0)),"",(IF(E13=1,30,IF(E13=2,20,IF(E13=3,10,IF(E13<>"",1,0))))+IF(F13=1,30,IF(F13=2,20,IF(F13=3,10,IF(F13<>"",1,0))))+IF(G13=1,30,IF(G13=2,20,IF(G13=3,10,IF(G13<>"",1,0))))+IF(H13=1,30,IF(H13=2,20,IF(H13=3,10,IF(H13<>"",1,0))))))
B14: ='👥 Участники'!B14 | C14: ='👥 Участники'!C14 | D14: ='👥 Участники'!D14 | I14: =IF(AND(C14="",OR(E14="",E14=0)),"",(IF(E14=1,30,IF(E14=2,20,IF(E14=3,10,IF(E14<>"",1,0))))+IF(F14=1,30,IF(F14=2,20,IF(F14=3,10,IF(F14<>"",1,0))))+IF(G14=1,30,IF(G14=2,20,IF(G14=3,10,IF(G14<>"",1,0))))+IF(H14=1,30,IF(H14=2,20,IF(H14=3,10,IF(H14<>"",1,0))))))
B15: ='👥 Участники'!B15 | C15: ='👥 Участники'!C15 | D15: ='👥 Участники'!D15 | I15: =IF(AND(C15="",OR(E15="",E15=0)),"",(IF(E15=1,30,IF(E15=2,20,IF(E15=3,10,IF(E15<>"",1,0))))+IF(F15=1,30,IF(F15=2,20,IF(F15=3,10,IF(F15<>"",1,0))))+IF(G15=1,30,IF(G15=2,20,IF(G15=3,10,IF(G15<>"",1,0))))+IF(H15=1,30,IF(H15=2,20,IF(H15=3,10,IF(H15<>"",1,0))))))
... B103: ='👥 Участники'!B103 | C103: ='👥 Участники'!C103 | D103: ='👥 Участники'!D103 | I103: =IF(AND(C103="",OR(E103="",E103=0)),"",(IF(E103=1,30,IF(E103=2,20,IF(E103=3,10,IF(E103<>"",1,0))))+IF(F103=1,30,IF(F103=2,20,IF(F103=3,10,IF(F103<>"",1,0))))+IF(G103=1,30,IF(G103=2,20,IF(G103=3,10,IF(G103<>"",1,0))))+IF(H103=1,30,IF(H103=2,20,IF(H103=3,10,IF(H103<>"",1,0))))))
I104: =IF(AND(C104="",OR(E104="",E104=0)),"",(IF(E104=1,30,IF(E104=2,20,IF(E104=3,10,IF(E104<>"",1,0))))+IF(F104=1,30,IF(F104=2,20,IF(F104=3,10,IF(F104<>"",1,0))))+IF(G104=1,30,IF(G104=2,20,IF(G104=3,10,IF(G104<>"",1,0))))+IF(H104=1,30,IF(H104=2,20,IF(H104=3,10,IF(H104<>"",1,0))))))
I105: =IF(AND(C105="",OR(E105="",E105=0)),"",(IF(E105=1,30,IF(E105=2,20,IF(E105=3,10,IF(E105<>"",1,0))))+IF(F105=1,30,IF(F105=2,20,IF(F105=3,10,IF(F105<>"",1,0))))+IF(G105=1,30,IF(G105=2,20,IF(G105=3,10,IF(G105<>"",1,0))))+IF(H105=1,30,IF(H105=2,20,IF(H105=3,10,IF(H105<>"",1,0))))))
I106: =IF(AND(C106="",OR(E106="",E106=0)),"",(IF(E106=1,30,IF(E106=2,20,IF(E106=3,10,IF(E106<>"",1,0))))+IF(F106=1,30,IF(F106=2,20,IF(F106=3,10,IF(F106<>"",1,0))))+IF(G106=1,30,IF(G106=2,20,IF(G106=3,10,IF(G106<>"",1,0))))+IF(H106=1,30,IF(H106=2,20,IF(H106=3,10,IF(H106<>"",1,0))))))
I107: =IF(AND(C107="",OR(E107="",E107=0)),"",(IF(E107=1,30,IF(E107=2,20,IF(E107=3,10,IF(E107<>"",1,0))))+IF(F107=1,30,IF(F107=2,20,IF(F107=3,10,IF(F107<>"",1,0))))+IF(G107=1,30,IF(G107=2,20,IF(G107=3,10,IF(G107<>"",1,0))))+IF(H107=1,30,IF(H107=2,20,IF(H107=3,10,IF(H107<>"",1,0))))))
I108: =IF(AND(C108="",OR(E108="",E108=0)),"",(IF(E108=1,30,IF(E108=2,20,IF(E108=3,10,IF(E108<>"",1,0))))+IF(F108=1,30,IF(F108=2,20,IF(F108=3,10,IF(F108<>"",1,0))))+IF(G108=1,30,IF(G108=2,20,IF(G108=3,10,IF(G108<>"",1,0))))+IF(H108=1,30,IF(H108=2,20,IF(H108=3,10,IF(H108<>"",1,0))))))
I109: =IF(AND(C109="",OR(E109="",E109=0)),"",(IF(E109=1,30,IF(E109=2,20,IF(E109=3,10,IF(E109<>"",1,0))))+IF(F109=1,30,IF(F109=2,20,IF(F109=3,10,IF(F109<>"",1,0))))+IF(G109=1,30,IF(G109=2,20,IF(G109=3,10,IF(G109<>"",1,0))))+IF(H109=1,30,IF(H109=2,20,IF(H109=3,10,IF(H109<>"",1,0))))))
I110: =IF(AND(C110="",OR(E110="",E110=0)),"",(IF(E110=1,30,IF(E110=2,20,IF(E110=3,10,IF(E110<>"",1,0))))+IF(F110=1,30,IF(F110=2,20,IF(F110=3,10,IF(F110<>"",1,0))))+IF(G110=1,30,IF(G110=2,20,IF(G110=3,10,IF(G110<>"",1,0))))+IF(H110=1,30,IF(H110=2,20,IF(H110=3,10,IF(H110<>"",1,0))))))
I111: =IF(AND(C111="",OR(E111="",E111=0)),"",(IF(E111=1,30,IF(E111=2,20,IF(E111=3,10,IF(E111<>"",1,0))))+IF(F111=1,30,IF(F111=2,20,IF(F111=3,10,IF(F111<>"",1,0))))+IF(G111=1,30,IF(G111=2,20,IF(G111=3,10,IF(G111<>"",1,0))))+IF(H111=1,30,IF(H111=2,20,IF(H111=3,10,IF(H111<>"",1,0))))))
I112: =IF(AND(C112="",OR(E112="",E112=0)),"",(IF(E112=1,30,IF(E112=2,20,IF(E112=3,10,IF(E112<>"",1,0))))+IF(F112=1,30,IF(F112=2,20,IF(F112=3,10,IF(F112<>"",1,0))))+IF(G112=1,30,IF(G112=2,20,IF(G112=3,10,IF(G112<>"",1,0))))+IF(H112=1,30,IF(H112=2,20,IF(H112=3,10,IF(H112<>"",1,0))))))
I113: =IF(AND(C113="",OR(E113="",E113=0)),"",(IF(E113=1,30,IF(E113=2,20,IF(E113=3,10,IF(E113<>"",1,0))))+IF(F113=1,30,IF(F113=2,20,IF(F113=3,10,IF(F113<>"",1,0))))+IF(G113=1,30,IF(G113=2,20,IF(G113=3,10,IF(G113<>"",1,0))))+IF(H113=1,30,IF(H113=2,20,IF(H113=3,10,IF(H113<>"",1,0))))))
I114: =IF(AND(C114="",OR(E114="",E114=0)),"",(IF(E114=1,30,IF(E114=2,20,IF(E114=3,10,IF(E114<>"",1,0))))+IF(F114=1,30,IF(F114=2,20,IF(F114=3,10,IF(F114<>"",1,0))))+IF(G114=1,30,IF(G114=2,20,IF(G114=3,10,IF(G114<>"",1,0))))+IF(H114=1,30,IF(H114=2,20,IF(H114=3,10,IF(H114<>"",1,0))))))
I115: =IF(AND(C115="",OR(E115="",E115=0)),"",(IF(E115=1,30,IF(E115=2,20,IF(E115=3,10,IF(E115<>"",1,0))))+IF(F115=1,30,IF(F115=2,20,IF(F115=3,10,IF(F115<>"",1,0))))+IF(G115=1,30,IF(G115=2,20,IF(G115=3,10,IF(G115<>"",1,0))))+IF(H115=1,30,IF(H115=2,20,IF(H115=3,10,IF(H115<>"",1,0))))))
... I1000: =IF(AND(C1000="",OR(E1000="",E1000=0)),"",(IF(E1000=1,30,IF(E1000=2,20,IF(E1000=3,10,IF(E1000<>"",1,0))))+IF(F1000=1,30,IF(F1000=2,20,IF(F1000=3,10,IF(F1000<>"",1,0))))+IF(G1000=1,30,IF(G1000=2,20,IF(G1000=3,10,IF(G1000<>"",1,0))))+IF(H1000=1,30,IF(H1000=2,20,IF(H1000=3,10,IF(H1000<>"",1,0))))))

Sheet ☀️ Summer
B2: ☀️ Summer — РЕЗУЛЬТАТЫ
B3: № | C3: Имя участника | D3: Номинация | E3: Место (осн.) | F3: Доп. ном.1 | G3: Доп. ном.2 | H3: Доп. ном.3 | I3: Баллы (x1)
B4: ='👥 Участники'!B4 | C4: ='👥 Участники'!C4 | D4: ='👥 Участники'!D4 | I4: =IF(AND(C4="",OR(E4="",E4=0)),"",(IF(E4=1,30,IF(E4=2,20,IF(E4=3,10,IF(E4<>"",1,0))))+IF(F4=1,30,IF(F4=2,20,IF(F4=3,10,IF(F4<>"",1,0))))+IF(G4=1,30,IF(G4=2,20,IF(G4=3,10,IF(G4<>"",1,0))))+IF(H4=1,30,IF(H4=2,20,IF(H4=3,10,IF(H4<>"",1,0))))))
B5: ='👥 Участники'!B5 | C5: ='👥 Участники'!C5 | D5: ='👥 Участники'!D5 | I5: =IF(AND(C5="",OR(E5="",E5=0)),"",(IF(E5=1,30,IF(E5=2,20,IF(E5=3,10,IF(E5<>"",1,0))))+IF(F5=1,30,IF(F5=2,20,IF(F5=3,10,IF(F5<>"",1,0))))+IF(G5=1,30,IF(G5=2,20,IF(G5=3,10,IF(G5<>"",1,0))))+IF(H5=1,30,IF(H5=2,20,IF(H5=3,10,IF(H5<>"",1,0))))))
B6: ='👥 Участники'!B6 | C6: ='👥 Участники'!C6 | D6: ='👥 Участники'!D6 | I6: =IF(AND(C6="",OR(E6="",E6=0)),"",(IF(E6=1,30,IF(E6=2,20,IF(E6=3,10,IF(E6<>"",1,0))))+IF(F6=1,30,IF(F6=2,20,IF(F6=3,10,IF(F6<>"",1,0))))+IF(G6=1,30,IF(G6=2,20,IF(G6=3,10,IF(G6<>"",1,0))))+IF(H6=1,30,IF(H6=2,20,IF(H6=3,10,IF(H6<>"",1,0))))))
B7: ='👥 Участники'!B7 | C7: ='👥 Участники'!C7 | D7: ='👥 Участники'!D7 | I7: =IF(AND(C7="",OR(E7="",E7=0)),"",(IF(E7=1,30,IF(E7=2,20,IF(E7=3,10,IF(E7<>"",1,0))))+IF(F7=1,30,IF(F7=2,20,IF(F7=3,10,IF(F7<>"",1,0))))+IF(G7=1,30,IF(G7=2,20,IF(G7=3,10,IF(G7<>"",1,0))))+IF(H7=1,30,IF(H7=2,20,IF(H7=3,10,IF(H7<>"",1,0))))))
B8: ='👥 Участники'!B8 | C8: ='👥 Участники'!C8 | D8: ='👥 Участники'!D8 | I8: =IF(AND(C8="",OR(E8="",E8=0)),"",(IF(E8=1,30,IF(E8=2,20,IF(E8=3,10,IF(E8<>"",1,0))))+IF(F8=1,30,IF(F8=2,20,IF(F8=3,10,IF(F8<>"",1,0))))+IF(G8=1,30,IF(G8=2,20,IF(G8=3,10,IF(G8<>"",1,0))))+IF(H8=1,30,IF(H8=2,20,IF(H8=3,10,IF(H8<>"",1,0))))))
B9: ='👥 Участники'!B9 | C9: ='👥 Участники'!C9 | D9: ='👥 Участники'!D9 | I9: =IF(AND(C9="",OR(E9="",E9=0)),"",(IF(E9=1,30,IF(E9=2,20,IF(E9=3,10,IF(E9<>"",1,0))))+IF(F9=1,30,IF(F9=2,20,IF(F9=3,10,IF(F9<>"",1,0))))+IF(G9=1,30,IF(G9=2,20,IF(G9=3,10,IF(G9<>"",1,0))))+IF(H9=1,30,IF(H9=2,20,IF(H9=3,10,IF(H9<>"",1,0))))))
B10: ='👥 Участники'!B10 | C10: ='👥 Участники'!C10 | D10: ='👥 Участники'!D10 | I10: =IF(AND(C10="",OR(E10="",E10=0)),"",(IF(E10=1,30,IF(E10=2,20,IF(E10=3,10,IF(E10<>"",1,0))))+IF(F10=1,30,IF(F10=2,20,IF(F10=3,10,IF(F10<>"",1,0))))+IF(G10=1,30,IF(G10=2,20,IF(G10=3,10,IF(G10<>"",1,0))))+IF(H10=1,30,IF(H10=2,20,IF(H10=3,10,IF(H10<>"",1,0))))))
B11: ='👥 Участники'!B11 | C11: ='👥 Участники'!C11 | D11: ='👥 Участники'!D11 | I11: =IF(AND(C11="",OR(E11="",E11=0)),"",(IF(E11=1,30,IF(E11=2,20,IF(E11=3,10,IF(E11<>"",1,0))))+IF(F11=1,30,IF(F11=2,20,IF(F11=3,10,IF(F11<>"",1,0))))+IF(G11=1,30,IF(G11=2,20,IF(G11=3,10,IF(G11<>"",1,0))))+IF(H11=1,30,IF(H11=2,20,IF(H11=3,10,IF(H11<>"",1,0))))))
B12: ='👥 Участники'!B12 | C12: ='👥 Участники'!C12 | D12: ='👥 Участники'!D12 | I12: =IF(AND(C12="",OR(E12="",E12=0)),"",(IF(E12=1,30,IF(E12=2,20,IF(E12=3,10,IF(E12<>"",1,0))))+IF(F12=1,30,IF(F12=2,20,IF(F12=3,10,IF(F12<>"",1,0))))+IF(G12=1,30,IF(G12=2,20,IF(G12=3,10,IF(G12<>"",1,0))))+IF(H12=1,30,IF(H12=2,20,IF(H12=3,10,IF(H12<>"",1,0))))))
B13: ='👥 Участники'!B13 | C13: ='👥 Участники'!C13 | D13: ='👥 Участники'!D13 | I13: =IF(AND(C13="",OR(E13="",E13=0)),"",(IF(E13=1,30,IF(E13=2,20,IF(E13=3,10,IF(E13<>"",1,0))))+IF(F13=1,30,IF(F13=2,20,IF(F13=3,10,IF(F13<>"",1,0))))+IF(G13=1,30,IF(G13=2,20,IF(G13=3,10,IF(G13<>"",1,0))))+IF(H13=1,30,IF(H13=2,20,IF(H13=3,10,IF(H13<>"",1,0))))))
B14: ='👥 Участники'!B14 | C14: ='👥 Участники'!C14 | D14: ='👥 Участники'!D14 | I14: =IF(AND(C14="",OR(E14="",E14=0)),"",(IF(E14=1,30,IF(E14=2,20,IF(E14=3,10,IF(E14<>"",1,0))))+IF(F14=1,30,IF(F14=2,20,IF(F14=3,10,IF(F14<>"",1,0))))+IF(G14=1,30,IF(G14=2,20,IF(G14=3,10,IF(G14<>"",1,0))))+IF(H14=1,30,IF(H14=2,20,IF(H14=3,10,IF(H14<>"",1,0))))))
B15: ='👥 Участники'!B15 | C15: ='👥 Участники'!C15 | D15: ='👥 Участники'!D15 | I15: =IF(AND(C15="",OR(E15="",E15=0)),"",(IF(E15=1,30,IF(E15=2,20,IF(E15=3,10,IF(E15<>"",1,0))))+IF(F15=1,30,IF(F15=2,20,IF(F15=3,10,IF(F15<>"",1,0))))+IF(G15=1,30,IF(G15=2,20,IF(G15=3,10,IF(G15<>"",1,0))))+IF(H15=1,30,IF(H15=2,20,IF(H15=3,10,IF(H15<>"",1,0))))))
... B103: ='👥 Участники'!B103 | C103: ='👥 Участники'!C103 | D103: ='👥 Участники'!D103 | I103: =IF(AND(C103="",OR(E103="",E103=0)),"",(IF(E103=1,30,IF(E103=2,20,IF(E103=3,10,IF(E103<>"",1,0))))+IF(F103=1,30,IF(F103=2,20,IF(F103=3,10,IF(F103<>"",1,0))))+IF(G103=1,30,IF(G103=2,20,IF(G103=3,10,IF(G103<>"",1,0))))+IF(H103=1,30,IF(H103=2,20,IF(H103=3,10,IF(H103<>"",1,0))))))
I104: =IF(AND(C104="",OR(E104="",E104=0)),"",(IF(E104=1,30,IF(E104=2,20,IF(E104=3,10,IF(E104<>"",1,0))))+IF(F104=1,30,IF(F104=2,20,IF(F104=3,10,IF(F104<>"",1,0))))+IF(G104=1,30,IF(G104=2,20,IF(G104=3,10,IF(G104<>"",1,0))))+IF(H104=1,30,IF(H104=2,20,IF(H104=3,10,IF(H104<>"",1,0))))))
I105: =IF(AND(C105="",OR(E105="",E105=0)),"",(IF(E105=1,30,IF(E105=2,20,IF(E105=3,10,IF(E105<>"",1,0))))+IF(F105=1,30,IF(F105=2,20,IF(F105=3,10,IF(F105<>"",1,0))))+IF(G105=1,30,IF(G105=2,20,IF(G105=3,10,IF(G105<>"",1,0))))+IF(H105=1,30,IF(H105=2,20,IF(H105=3,10,IF(H105<>"",1,0))))))
I106: =IF(AND(C106="",OR(E106="",E106=0)),"",(IF(E106=1,30,IF(E106=2,20,IF(E106=3,10,IF(E106<>"",1,0))))+IF(F106=1,30,IF(F106=2,20,IF(F106=3,10,IF(F106<>"",1,0))))+IF(G106=1,30,IF(G106=2,20,IF(G106=3,10,IF(G106<>"",1,0))))+IF(H106=1,30,IF(H106=2,20,IF(H106=3,10,IF(H106<>"",1,0))))))
I107: =IF(AND(C107="",OR(E107="",E107=0)),"",(IF(E107=1,30,IF(E107=2,20,IF(E107=3,10,IF(E107<>"",1,0))))+IF(F107=1,30,IF(F107=2,20,IF(F107=3,10,IF(F107<>"",1,0))))+IF(G107=1,30,IF(G107=2,20,IF(G107=3,10,IF(G107<>"",1,0))))+IF(H107=1,30,IF(H107=2,20,IF(H107=3,10,IF(H107<>"",1,0))))))
I108: =IF(AND(C108="",OR(E108="",E108=0)),"",(IF(E108=1,30,IF(E108=2,20,IF(E108=3,10,IF(E108<>"",1,0))))+IF(F108=1,30,IF(F108=2,20,IF(F108=3,10,IF(F108<>"",1,0))))+IF(G108=1,30,IF(G108=2,20,IF(G108=3,10,IF(G108<>"",1,0))))+IF(H108=1,30,IF(H108=2,20,IF(H108=3,10,IF(H108<>"",1,0))))))
I109: =IF(AND(C109="",OR(E109="",E109=0)),"",(IF(E109=1,30,IF(E109=2,20,IF(E109=3,10,IF(E109<>"",1,0))))+IF(F109=1,30,IF(F109=2,20,IF(F109=3,10,IF(F109<>"",1,0))))+IF(G109=1,30,IF(G109=2,20,IF(G109=3,10,IF(G109<>"",1,0))))+IF(H109=1,30,IF(H109=2,20,IF(H109=3,10,IF(H109<>"",1,0))))))
I110: =IF(AND(C110="",OR(E110="",E110=0)),"",(IF(E110=1,30,IF(E110=2,20,IF(E110=3,10,IF(E110<>"",1,0))))+IF(F110=1,30,IF(F110=2,20,IF(F110=3,10,IF(F110<>"",1,0))))+IF(G110=1,30,IF(G110=2,20,IF(G110=3,10,IF(G110<>"",1,0))))+IF(H110=1,30,IF(H110=2,20,IF(H110=3,10,IF(H110<>"",1,0))))))
I111: =IF(AND(C111="",OR(E111="",E111=0)),"",(IF(E111=1,30,IF(E111=2,20,IF(E111=3,10,IF(E111<>"",1,0))))+IF(F111=1,30,IF(F111=2,20,IF(F111=3,10,IF(F111<>"",1,0))))+IF(G111=1,30,IF(G111=2,20,IF(G111=3,10,IF(G111<>"",1,0))))+IF(H111=1,30,IF(H111=2,20,IF(H111=3,10,IF(H111<>"",1,0))))))
I112: =IF(AND(C112="",OR(E112="",E112=0)),"",(IF(E112=1,30,IF(E112=2,20,IF(E112=3,10,IF(E112<>"",1,0))))+IF(F112=1,30,IF(F112=2,20,IF(F112=3,10,IF(F112<>"",1,0))))+IF(G112=1,30,IF(G112=2,20,IF(G112=3,10,IF(G112<>"",1,0))))+IF(H112=1,30,IF(H112=2,20,IF(H112=3,10,IF(H112<>"",1,0))))))
I113: =IF(AND(C113="",OR(E113="",E113=0)),"",(IF(E113=1,30,IF(E113=2,20,IF(E113=3,10,IF(E113<>"",1,0))))+IF(F113=1,30,IF(F113=2,20,IF(F113=3,10,IF(F113<>"",1,0))))+IF(G113=1,30,IF(G113=2,20,IF(G113=3,10,IF(G113<>"",1,0))))+IF(H113=1,30,IF(H113=2,20,IF(H113=3,10,IF(H113<>"",1,0))))))
I114: =IF(AND(C114="",OR(E114="",E114=0)),"",(IF(E114=1,30,IF(E114=2,20,IF(E114=3,10,IF(E114<>"",1,0))))+IF(F114=1,30,IF(F114=2,20,IF(F114=3,10,IF(F114<>"",1,0))))+IF(G114=1,30,IF(G114=2,20,IF(G114=3,10,IF(G114<>"",1,0))))+IF(H114=1,30,IF(H114=2,20,IF(H114=3,10,IF(H114<>"",1,0))))))
I115: =IF(AND(C115="",OR(E115="",E115=0)),"",(IF(E115=1,30,IF(E115=2,20,IF(E115=3,10,IF(E115<>"",1,0))))+IF(F115=1,30,IF(F115=2,20,IF(F115=3,10,IF(F115<>"",1,0))))+IF(G115=1,30,IF(G115=2,20,IF(G115=3,10,IF(G115<>"",1,0))))+IF(H115=1,30,IF(H115=2,20,IF(H115=3,10,IF(H115<>"",1,0))))))
... I1000: =IF(AND(C1000="",OR(E1000="",E1000=0)),"",(IF(E1000=1,30,IF(E1000=2,20,IF(E1000=3,10,IF(E1000<>"",1,0))))+IF(F1000=1,30,IF(F1000=2,20,IF(F1000=3,10,IF(F1000<>"",1,0))))+IF(G1000=1,30,IF(G1000=2,20,IF(G1000=3,10,IF(G1000<>"",1,0))))+IF(H1000=1,30,IF(H1000=2,20,IF(H1000=3,10,IF(H1000<>"",1,0))))))

Sheet 🍂 Autumn
B2: 🍂 Autumn — РЕЗУЛЬТАТЫ
B3: № | C3: Имя участника | D3: Номинация | E3: Место (осн.) | F3: Доп. ном.1 | G3: Доп. ном.2 | H3: Доп. ном.3 | I3: Баллы (x1)
B4: ='👥 Участники'!B4 | C4: ='👥 Участники'!C4 | D4: ='👥 Участники'!D4 | I4: =IF(AND(C4="",OR(E4="",E4=0)),"",(IF(E4=1,30,IF(E4=2,20,IF(E4=3,10,IF(E4<>"",1,0))))+IF(F4=1,30,IF(F4=2,20,IF(F4=3,10,IF(F4<>"",1,0))))+IF(G4=1,30,IF(G4=2,20,IF(G4=3,10,IF(G4<>"",1,0))))+IF(H4=1,30,IF(H4=2,20,IF(H4=3,10,IF(H4<>"",1,0))))))
B5: ='👥 Участники'!B5 | C5: ='👥 Участники'!C5 | D5: ='👥 Участники'!D5 | I5: =IF(AND(C5="",OR(E5="",E5=0)),"",(IF(E5=1,30,IF(E5=2,20,IF(E5=3,10,IF(E5<>"",1,0))))+IF(F5=1,30,IF(F5=2,20,IF(F5=3,10,IF(F5<>"",1,0))))+IF(G5=1,30,IF(G5=2,20,IF(G5=3,10,IF(G5<>"",1,0))))+IF(H5=1,30,IF(H5=2,20,IF(H5=3,10,IF(H5<>"",1,0))))))
B6: ='👥 Участники'!B6 | C6: ='👥 Участники'!C6 | D6: ='👥 Участники'!D6 | I6: =IF(AND(C6="",OR(E6="",E6=0)),"",(IF(E6=1,30,IF(E6=2,20,IF(E6=3,10,IF(E6<>"",1,0))))+IF(F6=1,30,IF(F6=2,20,IF(F6=3,10,IF(F6<>"",1,0))))+IF(G6=1,30,IF(G6=2,20,IF(G6=3,10,IF(G6<>"",1,0))))+IF(H6=1,30,IF(H6=2,20,IF(H6=3,10,IF(H6<>"",1,0))))))
B7: ='👥 Участники'!B7 | C7: ='👥 Участники'!C7 | D7: ='👥 Участники'!D7 | I7: =IF(AND(C7="",OR(E7="",E7=0)),"",(IF(E7=1,30,IF(E7=2,20,IF(E7=3,10,IF(E7<>"",1,0))))+IF(F7=1,30,IF(F7=2,20,IF(F7=3,10,IF(F7<>"",1,0))))+IF(G7=1,30,IF(G7=2,20,IF(G7=3,10,IF(G7<>"",1,0))))+IF(H7=1,30,IF(H7=2,20,IF(H7=3,10,IF(H7<>"",1,0))))))
B8: ='👥 Участники'!B8 | C8: ='👥 Участники'!C8 | D8: ='👥 Участники'!D8 | I8: =IF(AND(C8="",OR(E8="",E8=0)),"",(IF(E8=1,30,IF(E8=2,20,IF(E8=3,10,IF(E8<>"",1,0))))+IF(F8=1,30,IF(F8=2,20,IF(F8=3,10,IF(F8<>"",1,0))))+IF(G8=1,30,IF(G8=2,20,IF(G8=3,10,IF(G8<>"",1,0))))+IF(H8=1,30,IF(H8=2,20,IF(H8=3,10,IF(H8<>"",1,0))))))
B9: ='👥 Участники'!B9 | C9: ='👥 Участники'!C9 | D9: ='👥 Участники'!D9 | I9: =IF(AND(C9="",OR(E9="",E9=0)),"",(IF(E9=1,30,IF(E9=2,20,IF(E9=3,10,IF(E9<>"",1,0))))+IF(F9=1,30,IF(F9=2,20,IF(F9=3,10,IF(F9<>"",1,0))))+IF(G9=1,30,IF(G9=2,20,IF(G9=3,10,IF(G9<>"",1,0))))+IF(H9=1,30,IF(H9=2,20,IF(H9=3,10,IF(H9<>"",1,0))))))
B10: ='👥 Участники'!B10 | C10: ='👥 Участники'!C10 | D10: ='👥 Участники'!D10 | I10: =IF(AND(C10="",OR(E10="",E10=0)),"",(IF(E10=1,30,IF(E10=2,20,IF(E10=3,10,IF(E10<>"",1,0))))+IF(F10=1,30,IF(F10=2,20,IF(F10=3,10,IF(F10<>"",1,0))))+IF(G10=1,30,IF(G10=2,20,IF(G10=3,10,IF(G10<>"",1,0))))+IF(H10=1,30,IF(H10=2,20,IF(H10=3,10,IF(H10<>"",1,0))))))
B11: ='👥 Участники'!B11 | C11: ='👥 Участники'!C11 | D11: ='👥 Участники'!D11 | I11: =IF(AND(C11="",OR(E11="",E11=0)),"",(IF(E11=1,30,IF(E11=2,20,IF(E11=3,10,IF(E11<>"",1,0))))+IF(F11=1,30,IF(F11=2,20,IF(F11=3,10,IF(F11<>"",1,0))))+IF(G11=1,30,IF(G11=2,20,IF(G11=3,10,IF(G11<>"",1,0))))+IF(H11=1,30,IF(H11=2,20,IF(H11=3,10,IF(H11<>"",1,0))))))
B12: ='👥 Участники'!B12 | C12: ='👥 Участники'!C12 | D12: ='👥 Участники'!D12 | I12: =IF(AND(C12="",OR(E12="",E12=0)),"",(IF(E12=1,30,IF(E12=2,20,IF(E12=3,10,IF(E12<>"",1,0))))+IF(F12=1,30,IF(F12=2,20,IF(F12=3,10,IF(F12<>"",1,0))))+IF(G12=1,30,IF(G12=2,20,IF(G12=3,10,IF(G12<>"",1,0))))+IF(H12=1,30,IF(H12=2,20,IF(H12=3,10,IF(H12<>"",1,0))))))
B13: ='👥 Участники'!B13 | C13: ='👥 Участники'!C13 | D13: ='👥 Участники'!D13 | I13: =IF(AND(C13="",OR(E13="",E13=0)),"",(IF(E13=1,30,IF(E13=2,20,IF(E13=3,10,IF(E13<>"",1,0))))+IF(F13=1,30,IF(F13=2,20,IF(F13=3,10,IF(F13<>"",1,0))))+IF(G13=1,30,IF(G13=2,20,IF(G13=3,10,IF(G13<>"",1,0))))+IF(H13=1,30,IF(H13=2,20,IF(H13=3,10,IF(H13<>"",1,0))))))
B14: ='👥 Участники'!B14 | C14: ='👥 Участники'!C14 | D14: ='👥 Участники'!D14 | I14: =IF(AND(C14="",OR(E14="",E14=0)),"",(IF(E14=1,30,IF(E14=2,20,IF(E14=3,10,IF(E14<>"",1,0))))+IF(F14=1,30,IF(F14=2,20,IF(F14=3,10,IF(F14<>"",1,0))))+IF(G14=1,30,IF(G14=2,20,IF(G14=3,10,IF(G14<>"",1,0))))+IF(H14=1,30,IF(H14=2,20,IF(H14=3,10,IF(H14<>"",1,0))))))
B15: ='👥 Участники'!B15 | C15: ='👥 Участники'!C15 | D15: ='👥 Участники'!D15 | I15: =IF(AND(C15="",OR(E15="",E15=0)),"",(IF(E15=1,30,IF(E15=2,20,IF(E15=3,10,IF(E15<>"",1,0))))+IF(F15=1,30,IF(F15=2,20,IF(F15=3,10,IF(F15<>"",1,0))))+IF(G15=1,30,IF(G15=2,20,IF(G15=3,10,IF(G15<>"",1,0))))+IF(H15=1,30,IF(H15=2,20,IF(H15=3,10,IF(H15<>"",1,0))))))
... B103: ='👥 Участники'!B103 | C103: ='👥 Участники'!C103 | D103: ='👥 Участники'!D103 | I103: =IF(AND(C103="",OR(E103="",E103=0)),"",(IF(E103=1,30,IF(E103=2,20,IF(E103=3,10,IF(E103<>"",1,0))))+IF(F103=1,30,IF(F103=2,20,IF(F103=3,10,IF(F103<>"",1,0))))+IF(G103=1,30,IF(G103=2,20,IF(G103=3,10,IF(G103<>"",1,0))))+IF(H103=1,30,IF(H103=2,20,IF(H103=3,10,IF(H103<>"",1,0))))))
I104: =IF(AND(C104="",OR(E104="",E104=0)),"",(IF(E104=1,30,IF(E104=2,20,IF(E104=3,10,IF(E104<>"",1,0))))+IF(F104=1,30,IF(F104=2,20,IF(F104=3,10,IF(F104<>"",1,0))))+IF(G104=1,30,IF(G104=2,20,IF(G104=3,10,IF(G104<>"",1,0))))+IF(H104=1,30,IF(H104=2,20,IF(H104=3,10,IF(H104<>"",1,0))))))
I105: =IF(AND(C105="",OR(E105="",E105=0)),"",(IF(E105=1,30,IF(E105=2,20,IF(E105=3,10,IF(E105<>"",1,0))))+IF(F105=1,30,IF(F105=2,20,IF(F105=3,10,IF(F105<>"",1,0))))+IF(G105=1,30,IF(G105=2,20,IF(G105=3,10,IF(G105<>"",1,0))))+IF(H105=1,30,IF(H105=2,20,IF(H105=3,10,IF(H105<>"",1,0))))))
I106: =IF(AND(C106="",OR(E106="",E106=0)),"",(IF(E106=1,30,IF(E106=2,20,IF(E106=3,10,IF(E106<>"",1,0))))+IF(F106=1,30,IF(F106=2,20,IF(F106=3,10,IF(F106<>"",1,0))))+IF(G106=1,30,IF(G106=2,20,IF(G106=3,10,IF(G106<>"",1,0))))+IF(H106=1,30,IF(H106=2,20,IF(H106=3,10,IF(H106<>"",1,0))))))
I107: =IF(AND(C107="",OR(E107="",E107=0)),"",(IF(E107=1,30,IF(E107=2,20,IF(E107=3,10,IF(E107<>"",1,0))))+IF(F107=1,30,IF(F107=2,20,IF(F107=3,10,IF(F107<>"",1,0))))+IF(G107=1,30,IF(G107=2,20,IF(G107=3,10,IF(G107<>"",1,0))))+IF(H107=1,30,IF(H107=2,20,IF(H107=3,10,IF(H107<>"",1,0))))))
I108: =IF(AND(C108="",OR(E108="",E108=0)),"",(IF(E108=1,30,IF(E108=2,20,IF(E108=3,10,IF(E108<>"",1,0))))+IF(F108=1,30,IF(F108=2,20,IF(F108=3,10,IF(F108<>"",1,0))))+IF(G108=1,30,IF(G108=2,20,IF(G108=3,10,IF(G108<>"",1,0))))+IF(H108=1,30,IF(H108=2,20,IF(H108=3,10,IF(H108<>"",1,0))))))
I109: =IF(AND(C109="",OR(E109="",E109=0)),"",(IF(E109=1,30,IF(E109=2,20,IF(E109=3,10,IF(E109<>"",1,0))))+IF(F109=1,30,IF(F109=2,20,IF(F109=3,10,IF(F109<>"",1,0))))+IF(G109=1,30,IF(G109=2,20,IF(G109=3,10,IF(G109<>"",1,0))))+IF(H109=1,30,IF(H109=2,20,IF(H109=3,10,IF(H109<>"",1,0))))))
I110: =IF(AND(C110="",OR(E110="",E110=0)),"",(IF(E110=1,30,IF(E110=2,20,IF(E110=3,10,IF(E110<>"",1,0))))+IF(F110=1,30,IF(F110=2,20,IF(F110=3,10,IF(F110<>"",1,0))))+IF(G110=1,30,IF(G110=2,20,IF(G110=3,10,IF(G110<>"",1,0))))+IF(H110=1,30,IF(H110=2,20,IF(H110=3,10,IF(H110<>"",1,0))))))
I111: =IF(AND(C111="",OR(E111="",E111=0)),"",(IF(E111=1,30,IF(E111=2,20,IF(E111=3,10,IF(E111<>"",1,0))))+IF(F111=1,30,IF(F111=2,20,IF(F111=3,10,IF(F111<>"",1,0))))+IF(G111=1,30,IF(G111=2,20,IF(G111=3,10,IF(G111<>"",1,0))))+IF(H111=1,30,IF(H111=2,20,IF(H111=3,10,IF(H111<>"",1,0))))))
I112: =IF(AND(C112="",OR(E112="",E112=0)),"",(IF(E112=1,30,IF(E112=2,20,IF(E112=3,10,IF(E112<>"",1,0))))+IF(F112=1,30,IF(F112=2,20,IF(F112=3,10,IF(F112<>"",1,0))))+IF(G112=1,30,IF(G112=2,20,IF(G112=3,10,IF(G112<>"",1,0))))+IF(H112=1,30,IF(H112=2,20,IF(H112=3,10,IF(H112<>"",1,0))))))
I113: =IF(AND(C113="",OR(E113="",E113=0)),"",(IF(E113=1,30,IF(E113=2,20,IF(E113=3,10,IF(E113<>"",1,0))))+IF(F113=1,30,IF(F113=2,20,IF(F113=3,10,IF(F113<>"",1,0))))+IF(G113=1,30,IF(G113=2,20,IF(G113=3,10,IF(G113<>"",1,0))))+IF(H113=1,30,IF(H113=2,20,IF(H113=3,10,IF(H113<>"",1,0))))))
I114: =IF(AND(C114="",OR(E114="",E114=0)),"",(IF(E114=1,30,IF(E114=2,20,IF(E114=3,10,IF(E114<>"",1,0))))+IF(F114=1,30,IF(F114=2,20,IF(F114=3,10,IF(F114<>"",1,0))))+IF(G114=1,30,IF(G114=2,20,IF(G114=3,10,IF(G114<>"",1,0))))+IF(H114=1,30,IF(H114=2,20,IF(H114=3,10,IF(H114<>"",1,0))))))
I115: =IF(AND(C115="",OR(E115="",E115=0)),"",(IF(E115=1,30,IF(E115=2,20,IF(E115=3,10,IF(E115<>"",1,0))))+IF(F115=1,30,IF(F115=2,20,IF(F115=3,10,IF(F115<>"",1,0))))+IF(G115=1,30,IF(G115=2,20,IF(G115=3,10,IF(G115<>"",1,0))))+IF(H115=1,30,IF(H115=2,20,IF(H115=3,10,IF(H115<>"",1,0))))))
... I1000: =IF(AND(C1000="",OR(E1000="",E1000=0)),"",(IF(E1000=1,30,IF(E1000=2,20,IF(E1000=3,10,IF(E1000<>"",1,0))))+IF(F1000=1,30,IF(F1000=2,20,IF(F1000=3,10,IF(F1000<>"",1,0))))+IF(G1000=1,30,IF(G1000=2,20,IF(G1000=3,10,IF(G1000<>"",1,0))))+IF(H1000=1,30,IF(H1000=2,20,IF(H1000=3,10,IF(H1000<>"",1,0))))))

Sheet 🔥 Final
B2: 🔥 Final — РЕЗУЛЬТАТЫ
B3: № | C3: Имя участника | D3: Номинация | E3: Место (осн.) | F3: Доп. ном.1 | G3: Доп. ном.2 | H3: Доп. ном.3 | I3: Баллы (x2 (Финал))
B4: ='👥 Участники'!B4 | C4: ='👥 Участники'!C4 | D4: ='👥 Участники'!D4 | I4: =IF(AND(C4="",OR(E4="",E4=0)),"",(IF(E4=1,30,IF(E4=2,20,IF(E4=3,10,IF(E4<>"",1,0))))+IF(F4=1,30,IF(F4=2,20,IF(F4=3,10,IF(F4<>"",1,0))))+IF(G4=1,30,IF(G4=2,20,IF(G4=3,10,IF(G4<>"",1,0))))+IF(H4=1,30,IF(H4=2,20,IF(H4=3,10,IF(H4<>"",1,0)))))*2)
B5: ='👥 Участники'!B5 | C5: ='👥 Участники'!C5 | D5: ='👥 Участники'!D5 | I5: =IF(AND(C5="",OR(E5="",E5=0)),"",(IF(E5=1,30,IF(E5=2,20,IF(E5=3,10,IF(E5<>"",1,0))))+IF(F5=1,30,IF(F5=2,20,IF(F5=3,10,IF(F5<>"",1,0))))+IF(G5=1,30,IF(G5=2,20,IF(G5=3,10,IF(G5<>"",1,0))))+IF(H5=1,30,IF(H5=2,20,IF(H5=3,10,IF(H5<>"",1,0)))))*2)
B6: ='👥 Участники'!B6 | C6: ='👥 Участники'!C6 | D6: ='👥 Участники'!D6 | I6: =IF(AND(C6="",OR(E6="",E6=0)),"",(IF(E6=1,30,IF(E6=2,20,IF(E6=3,10,IF(E6<>"",1,0))))+IF(F6=1,30,IF(F6=2,20,IF(F6=3,10,IF(F6<>"",1,0))))+IF(G6=1,30,IF(G6=2,20,IF(G6=3,10,IF(G6<>"",1,0))))+IF(H6=1,30,IF(H6=2,20,IF(H6=3,10,IF(H6<>"",1,0)))))*2)
B7: ='👥 Участники'!B7 | C7: ='👥 Участники'!C7 | D7: ='👥 Участники'!D7 | I7: =IF(AND(C7="",OR(E7="",E7=0)),"",(IF(E7=1,30,IF(E7=2,20,IF(E7=3,10,IF(E7<>"",1,0))))+IF(F7=1,30,IF(F7=2,20,IF(F7=3,10,IF(F7<>"",1,0))))+IF(G7=1,30,IF(G7=2,20,IF(G7=3,10,IF(G7<>"",1,0))))+IF(H7=1,30,IF(H7=2,20,IF(H7=3,10,IF(H7<>"",1,0)))))*2)
B8: ='👥 Участники'!B8 | C8: ='👥 Участники'!C8 | D8: ='👥 Участники'!D8 | I8: =IF(AND(C8="",OR(E8="",E8=0)),"",(IF(E8=1,30,IF(E8=2,20,IF(E8=3,10,IF(E8<>"",1,0))))+IF(F8=1,30,IF(F8=2,20,IF(F8=3,10,IF(F8<>"",1,0))))+IF(G8=1,30,IF(G8=2,20,IF(G8=3,10,IF(G8<>"",1,0))))+IF(H8=1,30,IF(H8=2,20,IF(H8=3,10,IF(H8<>"",1,0)))))*2)
B9: ='👥 Участники'!B9 | C9: ='👥 Участники'!C9 | D9: ='👥 Участники'!D9 | I9: =IF(AND(C9="",OR(E9="",E9=0)),"",(IF(E9=1,30,IF(E9=2,20,IF(E9=3,10,IF(E9<>"",1,0))))+IF(F9=1,30,IF(F9=2,20,IF(F9=3,10,IF(F9<>"",1,0))))+IF(G9=1,30,IF(G9=2,20,IF(G9=3,10,IF(G9<>"",1,0))))+IF(H9=1,30,IF(H9=2,20,IF(H9=3,10,IF(H9<>"",1,0)))))*2)
B10: ='👥 Участники'!B10 | C10: ='👥 Участники'!C10 | D10: ='👥 Участники'!D10 | I10: =IF(AND(C10="",OR(E10="",E10=0)),"",(IF(E10=1,30,IF(E10=2,20,IF(E10=3,10,IF(E10<>"",1,0))))+IF(F10=1,30,IF(F10=2,20,IF(F10=3,10,IF(F10<>"",1,0))))+IF(G10=1,30,IF(G10=2,20,IF(G10=3,10,IF(G10<>"",1,0))))+IF(H10=1,30,IF(H10=2,20,IF(H10=3,10,IF(H10<>"",1,0)))))*2)
B11: ='👥 Участники'!B11 | C11: ='👥 Участники'!C11 | D11: ='👥 Участники'!D11 | I11: =IF(AND(C11="",OR(E11="",E11=0)),"",(IF(E11=1,30,IF(E11=2,20,IF(E11=3,10,IF(E11<>"",1,0))))+IF(F11=1,30,IF(F11=2,20,IF(F11=3,10,IF(F11<>"",1,0))))+IF(G11=1,30,IF(G11=2,20,IF(G11=3,10,IF(G11<>"",1,0))))+IF(H11=1,30,IF(H11=2,20,IF(H11=3,10,IF(H11<>"",1,0)))))*2)
B12: ='👥 Участники'!B12 | C12: ='👥 Участники'!C12 | D12: ='👥 Участники'!D12 | I12: =IF(AND(C12="",OR(E12="",E12=0)),"",(IF(E12=1,30,IF(E12=2,20,IF(E12=3,10,IF(E12<>"",1,0))))+IF(F12=1,30,IF(F12=2,20,IF(F12=3,10,IF(F12<>"",1,0))))+IF(G12=1,30,IF(G12=2,20,IF(G12=3,10,IF(G12<>"",1,0))))+IF(H12=1,30,IF(H12=2,20,IF(H12=3,10,IF(H12<>"",1,0)))))*2)
B13: ='👥 Участники'!B13 | C13: ='👥 Участники'!C13 | D13: ='👥 Участники'!D13 | I13: =IF(AND(C13="",OR(E13="",E13=0)),"",(IF(E13=1,30,IF(E13=2,20,IF(E13=3,10,IF(E13<>"",1,0))))+IF(F13=1,30,IF(F13=2,20,IF(F13=3,10,IF(F13<>"",1,0))))+IF(G13=1,30,IF(G13=2,20,IF(G13=3,10,IF(G13<>"",1,0))))+IF(H13=1,30,IF(H13=2,20,IF(H13=3,10,IF(H13<>"",1,0)))))*2)
B14: ='👥 Участники'!B14 | C14: ='👥 Участники'!C14 | D14: ='👥 Участники'!D14 | I14: =IF(AND(C14="",OR(E14="",E14=0)),"",(IF(E14=1,30,IF(E14=2,20,IF(E14=3,10,IF(E14<>"",1,0))))+IF(F14=1,30,IF(F14=2,20,IF(F14=3,10,IF(F14<>"",1,0))))+IF(G14=1,30,IF(G14=2,20,IF(G14=3,10,IF(G14<>"",1,0))))+IF(H14=1,30,IF(H14=2,20,IF(H14=3,10,IF(H14<>"",1,0)))))*2)
B15: ='👥 Участники'!B15 | C15: ='👥 Участники'!C15 | D15: ='👥 Участники'!D15 | I15: =IF(AND(C15="",OR(E15="",E15=0)),"",(IF(E15=1,30,IF(E15=2,20,IF(E15=3,10,IF(E15<>"",1,0))))+IF(F15=1,30,IF(F15=2,20,IF(F15=3,10,IF(F15<>"",1,0))))+IF(G15=1,30,IF(G15=2,20,IF(G15=3,10,IF(G15<>"",1,0))))+IF(H15=1,30,IF(H15=2,20,IF(H15=3,10,IF(H15<>"",1,0)))))*2)
... B103: ='👥 Участники'!B103 | C103: ='👥 Участники'!C103 | D103: ='👥 Участники'!D103 | I103: =IF(AND(C103="",OR(E103="",E103=0)),"",(IF(E103=1,30,IF(E103=2,20,IF(E103=3,10,IF(E103<>"",1,0))))+IF(F103=1,30,IF(F103=2,20,IF(F103=3,10,IF(F103<>"",1,0))))+IF(G103=1,30,IF(G103=2,20,IF(G103=3,10,IF(G103<>"",1,0))))+IF(H103=1,30,IF(H103=2,20,IF(H103=3,10,IF(H103<>"",1,0)))))*2)
I104: =IF(AND(C104="",OR(E104="",E104=0)),"",(IF(E104=1,30,IF(E104=2,20,IF(E104=3,10,IF(E104<>"",1,0))))+IF(F104=1,30,IF(F104=2,20,IF(F104=3,10,IF(F104<>"",1,0))))+IF(G104=1,30,IF(G104=2,20,IF(G104=3,10,IF(G104<>"",1,0))))+IF(H104=1,30,IF(H104=2,20,IF(H104=3,10,IF(H104<>"",1,0)))))*2)
I105: =IF(AND(C105="",OR(E105="",E105=0)),"",(IF(E105=1,30,IF(E105=2,20,IF(E105=3,10,IF(E105<>"",1,0))))+IF(F105=1,30,IF(F105=2,20,IF(F105=3,10,IF(F105<>"",1,0))))+IF(G105=1,30,IF(G105=2,20,IF(G105=3,10,IF(G105<>"",1,0))))+IF(H105=1,30,IF(H105=2,20,IF(H105=3,10,IF(H105<>"",1,0)))))*2)
I106: =IF(AND(C106="",OR(E106="",E106=0)),"",(IF(E106=1,30,IF(E106=2,20,IF(E106=3,10,IF(E106<>"",1,0))))+IF(F106=1,30,IF(F106=2,20,IF(F106=3,10,IF(F106<>"",1,0))))+IF(G106=1,30,IF(G106=2,20,IF(G106=3,10,IF(G106<>"",1,0))))+IF(H106=1,30,IF(H106=2,20,IF(H106=3,10,IF(H106<>"",1,0)))))*2)
I107: =IF(AND(C107="",OR(E107="",E107=0)),"",(IF(E107=1,30,IF(E107=2,20,IF(E107=3,10,IF(E107<>"",1,0))))+IF(F107=1,30,IF(F107=2,20,IF(F107=3,10,IF(F107<>"",1,0))))+IF(G107=1,30,IF(G107=2,20,IF(G107=3,10,IF(G107<>"",1,0))))+IF(H107=1,30,IF(H107=2,20,IF(H107=3,10,IF(H107<>"",1,0)))))*2)
I108: =IF(AND(C108="",OR(E108="",E108=0)),"",(IF(E108=1,30,IF(E108=2,20,IF(E108=3,10,IF(E108<>"",1,0))))+IF(F108=1,30,IF(F108=2,20,IF(F108=3,10,IF(F108<>"",1,0))))+IF(G108=1,30,IF(G108=2,20,IF(G108=3,10,IF(G108<>"",1,0))))+IF(H108=1,30,IF(H108=2,20,IF(H108=3,10,IF(H108<>"",1,0)))))*2)
I109: =IF(AND(C109="",OR(E109="",E109=0)),"",(IF(E109=1,30,IF(E109=2,20,IF(E109=3,10,IF(E109<>"",1,0))))+IF(F109=1,30,IF(F109=2,20,IF(F109=3,10,IF(F109<>"",1,0))))+IF(G109=1,30,IF(G109=2,20,IF(G109=3,10,IF(G109<>"",1,0))))+IF(H109=1,30,IF(H109=2,20,IF(H109=3,10,IF(H109<>"",1,0)))))*2)
I110: =IF(AND(C110="",OR(E110="",E110=0)),"",(IF(E110=1,30,IF(E110=2,20,IF(E110=3,10,IF(E110<>"",1,0))))+IF(F110=1,30,IF(F110=2,20,IF(F110=3,10,IF(F110<>"",1,0))))+IF(G110=1,30,IF(G110=2,20,IF(G110=3,10,IF(G110<>"",1,0))))+IF(H110=1,30,IF(H110=2,20,IF(H110=3,10,IF(H110<>"",1,0)))))*2)
I111: =IF(AND(C111="",OR(E111="",E111=0)),"",(IF(E111=1,30,IF(E111=2,20,IF(E111=3,10,IF(E111<>"",1,0))))+IF(F111=1,30,IF(F111=2,20,IF(F111=3,10,IF(F111<>"",1,0))))+IF(G111=1,30,IF(G111=2,20,IF(G111=3,10,IF(G111<>"",1,0))))+IF(H111=1,30,IF(H111=2,20,IF(H111=3,10,IF(H111<>"",1,0)))))*2)
I112: =IF(AND(C112="",OR(E112="",E112=0)),"",(IF(E112=1,30,IF(E112=2,20,IF(E112=3,10,IF(E112<>"",1,0))))+IF(F112=1,30,IF(F112=2,20,IF(F112=3,10,IF(F112<>"",1,0))))+IF(G112=1,30,IF(G112=2,20,IF(G112=3,10,IF(G112<>"",1,0))))+IF(H112=1,30,IF(H112=2,20,IF(H112=3,10,IF(H112<>"",1,0)))))*2)
I113: =IF(AND(C113="",OR(E113="",E113=0)),"",(IF(E113=1,30,IF(E113=2,20,IF(E113=3,10,IF(E113<>"",1,0))))+IF(F113=1,30,IF(F113=2,20,IF(F113=3,10,IF(F113<>"",1,0))))+IF(G113=1,30,IF(G113=2,20,IF(G113=3,10,IF(G113<>"",1,0))))+IF(H113=1,30,IF(H113=2,20,IF(H113=3,10,IF(H113<>"",1,0)))))*2)
I114: =IF(AND(C114="",OR(E114="",E114=0)),"",(IF(E114=1,30,IF(E114=2,20,IF(E114=3,10,IF(E114<>"",1,0))))+IF(F114=1,30,IF(F114=2,20,IF(F114=3,10,IF(F114<>"",1,0))))+IF(G114=1,30,IF(G114=2,20,IF(G114=3,10,IF(G114<>"",1,0))))+IF(H114=1,30,IF(H114=2,20,IF(H114=3,10,IF(H114<>"",1,0)))))*2)
I115: =IF(AND(C115="",OR(E115="",E115=0)),"",(IF(E115=1,30,IF(E115=2,20,IF(E115=3,10,IF(E115<>"",1,0))))+IF(F115=1,30,IF(F115=2,20,IF(F115=3,10,IF(F115<>"",1,0))))+IF(G115=1,30,IF(G115=2,20,IF(G115=3,10,IF(G115<>"",1,0))))+IF(H115=1,30,IF(H115=2,20,IF(H115=3,10,IF(H115<>"",1,0)))))*2)
... I1000: =IF(AND(C1000="",OR(E1000="",E1000=0)),"",(IF(E1000=1,30,IF(E1000=2,20,IF(E1000=3,10,IF(E1000<>"",1,0))))+IF(F1000=1,30,IF(F1000=2,20,IF(F1000=3,10,IF(F1000<>"",1,0))))+IF(G1000=1,30,IF(G1000=2,20,IF(G1000=3,10,IF(G1000<>"",1,0))))+IF(H1000=1,30,IF(H1000=2,20,IF(H1000=3,10,IF(H1000<>"",1,0)))))*2)

Sheet 🏆 Дашборд
B2: 🏆 BREAK WAVE — ИТОГОВЫЙ ДАШБОРД
B3: Топ-3 в каждой номинации · При ничьей — все участники на одном месте
B5: 📗 1 год обучения | H5: 📘 до 3 лет опыта | N5: 📗 до 6 лет
B6: Участник(и) | F6: Баллы | H6: Участник(и) | L6: Баллы | N6: Участник(и) | R6: Баллы
B7: =IFERROR(__xludf.DUMMYFUNCTION("IFERROR(IF(COUNTIFS('📊 Общий рейтинг'!$D$4:$D$103,""1 год обучения"",'📊 Общий рейтинг'!$L$4:$L$103,1)=0,""—"",""🥇 ""&TEXTJOIN("", "",TRUE,FILTER('📊 Общий рейтинг'!$C$4:$C$103,('📊 Общий рейтинг'!$D$4:$D$103=""1 год обучения"")*('📊 Общий рейтинг'!$L$4"&":$L$103=1)))),""—"")"),"🥇 Bboy Max-Club, Bboy Фрол") | F7: =IFERROR(IF(COUNTIFS('📊 Общий рейтинг'!$D$4:$D$103,"1 год обучения",'📊 Общий рейтинг'!$L$4:$L$103,1)=0,"",MAXIFS('📊 Общий рейтинг'!$J$4:$J$103,'📊 Общий рейтинг'!$D$4:$D$103,"1 год обучения",'📊 Общий рейтинг'!$L$4:$L$103,1)),"") | H7: =IFERROR(__xludf.DUMMYFUNCTION("IFERROR(IF(COUNTIFS('📊 Общий рейтинг'!$D$4:$D$103,""до 3 лет опыта"",'📊 Общий рейтинг'!$L$4:$L$103,1)=0,""—"",""🥇 ""&TEXTJOIN("", "",TRUE,FILTER('📊 Общий рейтинг'!$C$4:$C$103,('📊 Общий рейтинг'!$D$4:$D$103=""до 3 лет опыта"")*('📊 Общий рейтинг'!$L$4"&":$L$103=1)))),""—"")"),"🥇 Bboy Batmort") | L7: =IFERROR(IF(COUNTIFS('📊 Общий рейтинг'!$D$4:$D$103,"до 3 лет опыта",'📊 Общий рейтинг'!$L$4:$L$103,1)=0,"",MAXIFS('📊 Общий рейтинг'!$J$4:$J$103,'📊 Общий рейтинг'!$D$4:$D$103,"до 3 лет опыта",'📊 Общий рейтинг'!$L$4:$L$103,1)),"") | N7: =IFERROR(__xludf.DUMMYFUNCTION("IFERROR(IF(COUNTIFS('📊 Общий рейтинг'!$D$4:$D$103,""до 6 лет"",'📊 Общий рейтинг'!$L$4:$L$103,1)=0,""—"",""🥇 ""&TEXTJOIN("", "",TRUE,FILTER('📊 Общий рейтинг'!$C$4:$C$103,('📊 Общий рейтинг'!$D$4:$D$103=""до 6 лет"")*('📊 Общий рейтинг'!$L$4:$L$103=1)))"&"),""—"")"),"🥇 Bboy Player") | R7: =IFERROR(IF(COUNTIFS('📊 Общий рейтинг'!$D$4:$D$103,"до 6 лет",'📊 Общий рейтинг'!$L$4:$L$103,1)=0,"",MAXIFS('📊 Общий рейтинг'!$J$4:$J$103,'📊 Общий рейтинг'!$D$4:$D$103,"до 6 лет",'📊 Общий рейтинг'!$L$4:$L$103,1)),"")
B8: =IFERROR(IF(COUNTIFS('📊 Общий рейтинг'!$D$4:$D$103,"1 год обучения",'📊 Общий рейтинг'!$L$4:$L$103,1)>1,"👥 "&COUNTIFS('📊 Общий рейтинг'!$D$4:$D$103,"1 год обучения",'📊 Общий рейтинг'!$L$4:$L$103,1)&" чел. на месте",""),"") | H8: =IFERROR(IF(COUNTIFS('📊 Общий рейтинг'!$D$4:$D$103,"до 3 лет опыта",'📊 Общий рейтинг'!$L$4:$L$103,1)>1,"👥 "&COUNTIFS('📊 Общий рейтинг'!$D$4:$D$103,"до 3 лет опыта",'📊 Общий рейтинг'!$L$4:$L$103,1)&" чел. на месте",""),"") | N8: =IFERROR(IF(COUNTIFS('📊 Общий рейтинг'!$D$4:$D$103,"до 6 лет",'📊 Общий рейтинг'!$L$4:$L$103,1)>1,"👥 "&COUNTIFS('📊 Общий рейтинг'!$D$4:$D$103,"до 6 лет",'📊 Общий рейтинг'!$L$4:$L$103,1)&" чел. на месте",""),"")
B10: =IFERROR(__xludf.DUMMYFUNCTION("IFERROR(IF(COUNTIFS('📊 Общий рейтинг'!$D$4:$D$103,""1 год обучения"",'📊 Общий рейтинг'!$L$4:$L$103,2)=0,""—"",""🥈 ""&TEXTJOIN("", "",TRUE,FILTER('📊 Общий рейтинг'!$C$4:$C$103,('📊 Общий рейтинг'!$D$4:$D$103=""1 год обучения"")*('📊 Общий рейтинг'!$L$4"&":$L$103=2)))),""—"")"),"—") | F10: =IFERROR(IF(COUNTIFS('📊 Общий рейтинг'!$D$4:$D$103,"1 год обучения",'📊 Общий рейтинг'!$L$4:$L$103,2)=0,"",MAXIFS('📊 Общий рейтинг'!$J$4:$J$103,'📊 Общий рейтинг'!$D$4:$D$103,"1 год обучения",'📊 Общий рейтинг'!$L$4:$L$103,2)),"") | H10: =IFERROR(__xludf.DUMMYFUNCTION("IFERROR(IF(COUNTIFS('📊 Общий рейтинг'!$D$4:$D$103,""до 3 лет опыта"",'📊 Общий рейтинг'!$L$4:$L$103,2)=0,""—"",""🥈 ""&TEXTJOIN("", "",TRUE,FILTER('📊 Общий рейтинг'!$C$4:$C$103,('📊 Общий рейтинг'!$D$4:$D$103=""до 3 лет опыта"")*('📊 Общий рейтинг'!$L$4"&":$L$103=2)))),""—"")"),"🥈 Bboy Лебедь, Bboy LaKostya") | L10: =IFERROR(IF(COUNTIFS('📊 Общий рейтинг'!$D$4:$D$103,"до 3 лет опыта",'📊 Общий рейтинг'!$L$4:$L$103,2)=0,"",MAXIFS('📊 Общий рейтинг'!$J$4:$J$103,'📊 Общий рейтинг'!$D$4:$D$103,"до 3 лет опыта",'📊 Общий рейтинг'!$L$4:$L$103,2)),"") | N10: =IFERROR(__xludf.DUMMYFUNCTION("IFERROR(IF(COUNTIFS('📊 Общий рейтинг'!$D$4:$D$103,""до 6 лет"",'📊 Общий рейтинг'!$L$4:$L$103,2)=0,""—"",""🥈 ""&TEXTJOIN("", "",TRUE,FILTER('📊 Общий рейтинг'!$C$4:$C$103,('📊 Общий рейтинг'!$D$4:$D$103=""до 6 лет"")*('📊 Общий рейтинг'!$L$4:$L$103=2)))"&"),""—"")"),"🥈 Bboy King") | R10: =IFERROR(IF(COUNTIFS('📊 Общий рейтинг'!$D$4:$D$103,"до 6 лет",'📊 Общий рейтинг'!$L$4:$L$103,2)=0,"",MAXIFS('📊 Общий рейтинг'!$J$4:$J$103,'📊 Общий рейтинг'!$D$4:$D$103,"до 6 лет",'📊 Общий рейтинг'!$L$4:$L$103,2)),"")
B11: =IFERROR(IF(COUNTIFS('📊 Общий рейтинг'!$D$4:$D$103,"1 год обучения",'📊 Общий рейтинг'!$L$4:$L$103,2)>1,"👥 "&COUNTIFS('📊 Общий рейтинг'!$D$4:$D$103,"1 год обучения",'📊 Общий рейтинг'!$L$4:$L$103,2)&" чел. на месте",""),"") | H11: =IFERROR(IF(COUNTIFS('📊 Общий рейтинг'!$D$4:$D$103,"до 3 лет опыта",'📊 Общий рейтинг'!$L$4:$L$103,2)>1,"👥 "&COUNTIFS('📊 Общий рейтинг'!$D$4:$D$103,"до 3 лет опыта",'📊 Общий рейтинг'!$L$4:$L$103,2)&" чел. на месте",""),"") | N11: =IFERROR(IF(COUNTIFS('📊 Общий рейтинг'!$D$4:$D$103,"до 6 лет",'📊 Общий рейтинг'!$L$4:$L$103,2)>1,"👥 "&COUNTIFS('📊 Общий рейтинг'!$D$4:$D$103,"до 6 лет",'📊 Общий рейтинг'!$L$4:$L$103,2)&" чел. на месте",""),"")
B13: =IFERROR(__xludf.DUMMYFUNCTION("IFERROR(IF(COUNTIFS('📊 Общий рейтинг'!$D$4:$D$103,""1 год обучения"",'📊 Общий рейтинг'!$L$4:$L$103,3)=0,""—"",""🥉 ""&TEXTJOIN("", "",TRUE,FILTER('📊 Общий рейтинг'!$C$4:$C$103,('📊 Общий рейтинг'!$D$4:$D$103=""1 год обучения"")*('📊 Общий рейтинг'!$L$4"&":$L$103=3)))),""—"")"),"🥉 Bboy Nazаr") | F13: =IFERROR(IF(COUNTIFS('📊 Общий рейтинг'!$D$4:$D$103,"1 год обучения",'📊 Общий рейтинг'!$L$4:$L$103,3)=0,"",MAXIFS('📊 Общий рейтинг'!$J$4:$J$103,'📊 Общий рейтинг'!$D$4:$D$103,"1 год обучения",'📊 Общий рейтинг'!$L$4:$L$103,3)),"") | H13: =IFERROR(__xludf.DUMMYFUNCTION("IFERROR(IF(COUNTIFS('📊 Общий рейтинг'!$D$4:$D$103,""до 3 лет опыта"",'📊 Общий рейтинг'!$L$4:$L$103,3)=0,""—"",""🥉 ""&TEXTJOIN("", "",TRUE,FILTER('📊 Общий рейтинг'!$C$4:$C$103,('📊 Общий рейтинг'!$D$4:$D$103=""до 3 лет опыта"")*('📊 Общий рейтинг'!$L$4"&":$L$103=3)))),""—"")"),"—") | L13: =IFERROR(IF(COUNTIFS('📊 Общий рейтинг'!$D$4:$D$103,"до 3 лет опыта",'📊 Общий рейтинг'!$L$4:$L$103,3)=0,"",MAXIFS('📊 Общий рейтинг'!$J$4:$J$103,'📊 Общий рейтинг'!$D$4:$D$103,"до 3 лет опыта",'📊 Общий рейтинг'!$L$4:$L$103,3)),"") | N13: =IFERROR(__xludf.DUMMYFUNCTION("IFERROR(IF(COUNTIFS('📊 Общий рейтинг'!$D$4:$D$103,""до 6 лет"",'📊 Общий рейтинг'!$L$4:$L$103,3)=0,""—"",""🥉 ""&TEXTJOIN("", "",TRUE,FILTER('📊 Общий рейтинг'!$C$4:$C$103,('📊 Общий рейтинг'!$D$4:$D$103=""до 6 лет"")*('📊 Общий рейтинг'!$L$4:$L$103=3)))"&"),""—"")"),"—") | R13: =IFERROR(IF(COUNTIFS('📊 Общий рейтинг'!$D$4:$D$103,"до 6 лет",'📊 Общий рейтинг'!$L$4:$L$103,3)=0,"",MAXIFS('📊 Общий рейтинг'!$J$4:$J$103,'📊 Общий рейтинг'!$D$4:$D$103,"до 6 лет",'📊 Общий рейтинг'!$L$4:$L$103,3)),"")
B14: =IFERROR(IF(COUNTIFS('📊 Общий рейтинг'!$D$4:$D$103,"1 год обучения",'📊 Общий рейтинг'!$L$4:$L$103,3)>1,"👥 "&COUNTIFS('📊 Общий рейтинг'!$D$4:$D$103,"1 год обучения",'📊 Общий рейтинг'!$L$4:$L$103,3)&" чел. на месте",""),"") | H14: =IFERROR(IF(COUNTIFS('📊 Общий рейтинг'!$D$4:$D$103,"до 3 лет опыта",'📊 Общий рейтинг'!$L$4:$L$103,3)>1,"👥 "&COUNTIFS('📊 Общий рейтинг'!$D$4:$D$103,"до 3 лет опыта",'📊 Общий рейтинг'!$L$4:$L$103,3)&" чел. на месте",""),"") | N14: =IFERROR(IF(COUNTIFS('📊 Общий рейтинг'!$D$4:$D$103,"до 6 лет",'📊 Общий рейтинг'!$L$4:$L$103,3)>1,"👥 "&COUNTIFS('📊 Общий рейтинг'!$D$4:$D$103,"до 6 лет",'📊 Общий рейтинг'!$L$4:$L$103,3)&" чел. на месте",""),"")
B17: 📙 7-9 лет | H17: 📕 10-13 лет | N17: 🌟 Kids Pro
B18: Участник(и) | F18: Баллы | H18: Участник(и) | L18: Баллы | N18: Участник(и) | R18: Баллы
B19: =IFERROR(__xludf.DUMMYFUNCTION("IFERROR(IF(COUNTIFS('📊 Общий рейтинг'!$D$4:$D$103,""7-9 лет"",'📊 Общий рейтинг'!$L$4:$L$103,1)=0,""—"",""🥇 ""&TEXTJOIN("", "",TRUE,FILTER('📊 Общий рейтинг'!$C$4:$C$103,('📊 Общий рейтинг'!$D$4:$D$103=""7-9 лет"")*('📊 Общий рейтинг'!$L$4:$L$103=1)))),"&"""—"")"),"—") | F19: =IFERROR(IF(COUNTIFS('📊 Общий рейтинг'!$D$4:$D$103,"7-9 лет",'📊 Общий рейтинг'!$L$4:$L$103,1)=0,"",MAXIFS('📊 Общий рейтинг'!$J$4:$J$103,'📊 Общий рейтинг'!$D$4:$D$103,"7-9 лет",'📊 Общий рейтинг'!$L$4:$L$103,1)),"") | H19: =IFERROR(__xludf.DUMMYFUNCTION("IFERROR(IF(COUNTIFS('📊 Общий рейтинг'!$D$4:$D$103,""10-13 лет"",'📊 Общий рейтинг'!$L$4:$L$103,1)=0,""—"",""🥇 ""&TEXTJOIN("", "",TRUE,FILTER('📊 Общий рейтинг'!$C$4:$C$103,('📊 Общий рейтинг'!$D$4:$D$103=""10-13 лет"")*('📊 Общий рейтинг'!$L$4:$L$103=1)"&"))),""—"")"),"🥇 Bboy Harlan") | L19: =IFERROR(IF(COUNTIFS('📊 Общий рейтинг'!$D$4:$D$103,"10-13 лет",'📊 Общий рейтинг'!$L$4:$L$103,1)=0,"",MAXIFS('📊 Общий рейтинг'!$J$4:$J$103,'📊 Общий рейтинг'!$D$4:$D$103,"10-13 лет",'📊 Общий рейтинг'!$L$4:$L$103,1)),"") | N19: =IFERROR(__xludf.DUMMYFUNCTION("IFERROR(IF(COUNTIFS('📊 Общий рейтинг'!$D$4:$D$103,""Kids Pro"",'📊 Общий рейтинг'!$L$4:$L$103,1)=0,""—"",""🥇 ""&TEXTJOIN("", "",TRUE,FILTER('📊 Общий рейтинг'!$C$4:$C$103,('📊 Общий рейтинг'!$D$4:$D$103=""Kids Pro"")*('📊 Общий рейтинг'!$L$4:$L$103=1)))"&"),""—"")"),"🥇 Bboy Brock") | R19: =IFERROR(IF(COUNTIFS('📊 Общий рейтинг'!$D$4:$D$103,"Kids Pro",'📊 Общий рейтинг'!$L$4:$L$103,1)=0,"",MAXIFS('📊 Общий рейтинг'!$J$4:$J$103,'📊 Общий рейтинг'!$D$4:$D$103,"Kids Pro",'📊 Общий рейтинг'!$L$4:$L$103,1)),"")
B20: =IFERROR(IF(COUNTIFS('📊 Общий рейтинг'!$D$4:$D$103,"7-9 лет",'📊 Общий рейтинг'!$L$4:$L$103,1)>1,"👥 "&COUNTIFS('📊 Общий рейтинг'!$D$4:$D$103,"7-9 лет",'📊 Общий рейтинг'!$L$4:$L$103,1)&" чел. на месте",""),"") | H20: =IFERROR(IF(COUNTIFS('📊 Общий рейтинг'!$D$4:$D$103,"10-13 лет",'📊 Общий рейтинг'!$L$4:$L$103,1)>1,"👥 "&COUNTIFS('📊 Общий рейтинг'!$D$4:$D$103,"10-13 лет",'📊 Общий рейтинг'!$L$4:$L$103,1)&" чел. на месте",""),"") | N20: =IFERROR(IF(COUNTIFS('📊 Общий рейтинг'!$D$4:$D$103,"Kids Pro",'📊 Общий рейтинг'!$L$4:$L$103,1)>1,"👥 "&COUNTIFS('📊 Общий рейтинг'!$D$4:$D$103,"Kids Pro",'📊 Общий рейтинг'!$L$4:$L$103,1)&" чел. на месте",""),"")
B22: =IFERROR(__xludf.DUMMYFUNCTION("IFERROR(IF(COUNTIFS('📊 Общий рейтинг'!$D$4:$D$103,""7-9 лет"",'📊 Общий рейтинг'!$L$4:$L$103,2)=0,""—"",""🥈 ""&TEXTJOIN("", "",TRUE,FILTER('📊 Общий рейтинг'!$C$4:$C$103,('📊 Общий рейтинг'!$D$4:$D$103=""7-9 лет"")*('📊 Общий рейтинг'!$L$4:$L$103=2)))),"&"""—"")"),"—") | F22: =IFERROR(IF(COUNTIFS('📊 Общий рейтинг'!$D$4:$D$103,"7-9 лет",'📊 Общий рейтинг'!$L$4:$L$103,2)=0,"",MAXIFS('📊 Общий рейтинг'!$J$4:$J$103,'📊 Общий рейтинг'!$D$4:$D$103,"7-9 лет",'📊 Общий рейтинг'!$L$4:$L$103,2)),"") | H22: =IFERROR(__xludf.DUMMYFUNCTION("IFERROR(IF(COUNTIFS('📊 Общий рейтинг'!$D$4:$D$103,""10-13 лет"",'📊 Общий рейтинг'!$L$4:$L$103,2)=0,""—"",""🥈 ""&TEXTJOIN("", "",TRUE,FILTER('📊 Общий рейтинг'!$C$4:$C$103,('📊 Общий рейтинг'!$D$4:$D$103=""10-13 лет"")*('📊 Общий рейтинг'!$L$4:$L$103=2)"&"))),""—"")"),"🥈 Bboy Wind") | L22: =IFERROR(IF(COUNTIFS('📊 Общий рейтинг'!$D$4:$D$103,"10-13 лет",'📊 Общий рейтинг'!$L$4:$L$103,2)=0,"",MAXIFS('📊 Общий рейтинг'!$J$4:$J$103,'📊 Общий рейтинг'!$D$4:$D$103,"10-13 лет",'📊 Общий рейтинг'!$L$4:$L$103,2)),"") | N22: =IFERROR(__xludf.DUMMYFUNCTION("IFERROR(IF(COUNTIFS('📊 Общий рейтинг'!$D$4:$D$103,""Kids Pro"",'📊 Общий рейтинг'!$L$4:$L$103,2)=0,""—"",""🥈 ""&TEXTJOIN("", "",TRUE,FILTER('📊 Общий рейтинг'!$C$4:$C$103,('📊 Общий рейтинг'!$D$4:$D$103=""Kids Pro"")*('📊 Общий рейтинг'!$L$4:$L$103=2)))"&"),""—"")"),"🥈 Bboy Kalos") | R22: =IFERROR(IF(COUNTIFS('📊 Общий рейтинг'!$D$4:$D$103,"Kids Pro",'📊 Общий рейтинг'!$L$4:$L$103,2)=0,"",MAXIFS('📊 Общий рейтинг'!$J$4:$J$103,'📊 Общий рейтинг'!$D$4:$D$103,"Kids Pro",'📊 Общий рейтинг'!$L$4:$L$103,2)),"")
B23: =IFERROR(IF(COUNTIFS('📊 Общий рейтинг'!$D$4:$D$103,"7-9 лет",'📊 Общий рейтинг'!$L$4:$L$103,2)>1,"👥 "&COUNTIFS('📊 Общий рейтинг'!$D$4:$D$103,"7-9 лет",'📊 Общий рейтинг'!$L$4:$L$103,2)&" чел. на месте",""),"") | H23: =IFERROR(IF(COUNTIFS('📊 Общий рейтинг'!$D$4:$D$103,"10-13 лет",'📊 Общий рейтинг'!$L$4:$L$103,2)>1,"👥 "&COUNTIFS('📊 Общий рейтинг'!$D$4:$D$103,"10-13 лет",'📊 Общий рейтинг'!$L$4:$L$103,2)&" чел. на месте",""),"") | N23: =IFERROR(IF(COUNTIFS('📊 Общий рейтинг'!$D$4:$D$103,"Kids Pro",'📊 Общий рейтинг'!$L$4:$L$103,2)>1,"👥 "&COUNTIFS('📊 Общий рейтинг'!$D$4:$D$103,"Kids Pro",'📊 Общий рейтинг'!$L$4:$L$103,2)&" чел. на месте",""),"")
